Workbook

Sheet Lucy Electric Price List
A1: Lucy Electric Aegis Plus Medium Voltage Switchgear Price List & Technical Catalogue
A2: Prices in USD ($) / GBP / Upon Request as per Lucy Electric Aegis Plus Technical Brochure (Ref: LEAEGP0121). Enter Discount as % (e.g. 20%); Net Price = Price x (1 - Discount).
A4: Sr. No. | B4: Manufacturer | C4: Category | D4: Description | E4: Key word | F4: Rating 1 | G4: Rating 2 | H4: Rating 3 | I4: Rating 4 | J4: Rating 5 | K4: Accessories | L4: Stocked or Not stocked | M4: Part code | N4: Discount | O4: Price | P4: Net Price | Q4: Product Range / Series | R4: Other Ratings / Specs | S4: Suitable for (Accessories) | T4: Std Pack | U4: Remarks | V4: Price List Page
A5: 1 | B5: Lucy Electric | C5: Ring Main Unit (RMU) | D5: 3-Function Ring Main Unit (2x 630A Load Break Switches + 1x 200A Switch Fuse) | E5: Aegis Plus LLF 12kV IP41 | F5: Voltage: 12kV | G5: In (A): 630 | H5: Withstand: 21kA 3s | I5: Extensibility: Non-Extensible | J5: Ingress: IP41 (Indoor) | K5: Complete Assembly | L5: Configured to Order | M5: AGP-NE-LLF-12kV-IP41 | O5: Upon request | P5: =IF(ISNUMBER(O5),O5*(1-N5),O5) | Q5: Aegis Plus | R5: Dimensions: 1050 x 785 x 1430 mm; Hermetically sealed SF6 stainless steel tank IP67; Peak withstand: 52.5kA; Lightning impulse: 75/125kV; Power freq: 28/50kV; Internal arc: IAC AF/AFL/AFLR 20kA 1s; DIN 400 Type C bushings; Bushing height: 450/600/750mm; Operating pressure: 0.03 MPa | S5: Secondary Distribution / Compact Substations | T5: 1 | U5: Factory assembled, SF6 insulated, robotic welded tank; 30+ year service life | V5: 10
A6: 2 | B6: Lucy Electric | C6: Ring Main Unit (RMU) | D6: 3-Function Ring Main Unit (2x 630A Load Break Switches + 1x 200A Switch Fuse) | E6: Aegis Plus LLF 24kV IP41 | F6: Voltage: 24kV | G6: In (A): 630 | H6: Withstand: 21kA 3s | I6: Extensibility: Non-Extensible | J6: Ingress: IP41 (Indoor) | K6: Complete Assembly | L6: Configured to Order | M6: AGP-NE-LLF-24kV-IP41 | O6: Upon request | P6: =IF(ISNUMBER(O6),O6*(1-N6),O6) | Q6: Aegis Plus | R6: Dimensions: 1050 x 785 x 1430 mm; Hermetically sealed SF6 stainless steel tank IP67; Peak withstand: 52.5kA; Lightning impulse: 75/125kV; Power freq: 28/50kV; Internal arc: IAC AF/AFL/AFLR 20kA 1s; DIN 400 Type C bushings; Bushing height: 450/600/750mm; Operating pressure: 0.03 MPa | S6: Secondary Distribution / Compact Substations | T6: 1 | U6: Factory assembled, SF6 insulated, robotic welded tank; 30+ year service life | V6: 10
A7: 3 | B7: Lucy Electric | C7: Ring Main Unit (RMU) | D7: 3-Function Ring Main Unit (2x 630A Load Break Switches + 1x 200A Switch Fuse) - Outdoor | E7: Aegis Plus LLF 12kV IP54 | F7: Voltage: 12kV | G7: In (A): 630 | H7: Withstand: 21kA 3s | I7: Extensibility: Non-Extensible | J7: Ingress: IP54 (Outdoor) | K7: Complete Assembly | L7: Configured to Order | M7: AGP-NE-LLF-12kV-IP54 | O7: Upon request | P7: =IF(ISNUMBER(O7),O7*(1-N7),O7) | Q7: Aegis Plus | R7: Dimensions: 1050 x 785 x 1440 mm; Hermetically sealed SF6 stainless steel tank IP67; Peak withstand: 52.5kA; Lightning impulse: 75/125kV; Power freq: 28/50kV; Internal arc: IAC AF/AFL/AFLR 20kA 1s; DIN 400 Type C bushings; Bushing height: 450/600/750mm; Operating pressure: 0.03 MPa | S7: Secondary Distribution / Compact Substations | T7: 1 | U7: Factory assembled, SF6 insulated, robotic welded tank; 30+ year service life | V7: 10
A8: 4 | B8: Lucy Electric | C8: Ring Main Unit (RMU) | D8: 3-Function Ring Main Unit (2x 630A Load Break Switches + 1x 200A Switch Fuse) - Outdoor | E8: Aegis Plus LLF 24kV IP54 | F8: Voltage: 24kV | G8: In (A): 630 | H8: Withstand: 21kA 3s | I8: Extensibility: Non-Extensible | J8: Ingress: IP54 (Outdoor) | K8: Complete Assembly | L8: Configured to Order | M8: AGP-NE-LLF-24kV-IP54 | O8: Upon request | P8: =IF(ISNUMBER(O8),O8*(1-N8),O8) | Q8: Aegis Plus | R8: Dimensions: 1050 x 785 x 1440 mm; Hermetically sealed SF6 stainless steel tank IP67; Peak withstand: 52.5kA; Lightning impulse: 75/125kV; Power freq: 28/50kV; Internal arc: IAC AF/AFL/AFLR 20kA 1s; DIN 400 Type C bushings; Bushing height: 450/600/750mm; Operating pressure: 0.03 MPa | S8: Secondary Distribution / Compact Substations | T8: 1 | U8: Factory assembled, SF6 insulated, robotic welded tank; 30+ year service life | V8: 10
A9: 5 | B9: Lucy Electric | C9: Ring Main Unit (RMU) | D9: 3-Function Ring Main Unit (2x 630A Load Break Switches + 1x 630A Vacuum Circuit Breaker) | E9: Aegis Plus LLV 12kV IP41 | F9: Voltage: 12kV | G9: In (A): 630 | H9: Withstand: 21kA 3s | I9: Extensibility: Non-Extensible | J9: Ingress: IP41 (Indoor) | K9: Complete Assembly | L9: Configured to Order | M9: AGP-NE-LLV-12kV-IP41 | O9: Upon request | P9: =IF(ISNUMBER(O9),O9*(1-N9),O9) | Q9: Aegis Plus | R9: Dimensions: 1050 x 715 x 1430 mm; Hermetically sealed SF6 stainless steel tank IP67; Peak withstand: 52.5kA; Lightning impulse: 75/125kV; Power freq: 28/50kV; Internal arc: IAC AF/AFL/AFLR 20kA 1s; DIN 400 Type C bushings; Bushing height: 450/600/750mm; Operating pressure: 0.03 MPa | S9: Secondary Distribution / Compact Substations | T9: 1 | U9: Factory assembled, SF6 insulated, robotic welded tank; 30+ year service life | V9: 10
A10: 6 | B10: Lucy Electric | C10: Ring Main Unit (RMU) | D10: 3-Function Ring Main Unit (2x 630A Load Break Switches + 1x 630A Vacuum Circuit Breaker) | E10: Aegis Plus LLV 17.5kV IP41 | F10: Voltage: 17.5kV | G10: In (A): 630 | H10: Withstand: 21kA 3s | I10: Extensibility: Non-Extensible | J10: Ingress: IP41 (Indoor) | K10: Complete Assembly | L10: Configured to Order | M10: AGP-NE-LLV-17.5kV-IP41 | O10: Upon request | P10: =IF(ISNUMBER(O10),O10*(1-N10),O10) | Q10: Aegis Plus | R10: Dimensions: 1050 x 715 x 1430 mm; Hermetically sealed SF6 stainless steel tank IP67; Peak withstand: 52.5kA; Lightning impulse: 75/125kV; Power freq: 28/50kV; Internal arc: IAC AF/AFL/AFLR 20kA 1s; DIN 400 Type C bushings; Bushing height: 450/600/750mm; Operating pressure: 0.03 MPa | S10: Secondary Distribution / Compact Substations | T10: 1 | U10: Factory assembled, SF6 insulated, robotic welded tank; 30+ year service life | V10: 10
A11: 7 | B11: Lucy Electric | C11: Ring Main Unit (RMU) | D11: 3-Function Ring Main Unit (2x 630A Load Break Switches + 1x 630A Vacuum Circuit Breaker) | E11: Aegis Plus LLV 24kV IP41 | F11: Voltage: 24kV | G11: In (A): 630 | H11: Withstand: 21kA 3s | I11: Extensibility: Non-Extensible | J11: Ingress: IP41 (Indoor) | K11: Complete Assembly | L11: Configured to Order | M11: AGP-NE-LLV-24kV-IP41 | O11: Upon request | P11: =IF(ISNUMBER(O11),O11*(1-N11),O11) | Q11: Aegis Plus | R11: Dimensions: 1050 x 715 x 1430 mm; Hermetically sealed SF6 stainless steel tank IP67; Peak withstand: 52.5kA; Lightning impulse: 75/125kV; Power freq: 28/50kV; Internal arc: IAC AF/AFL/AFLR 20kA 1s; DIN 400 Type C bushings; Bushing height: 450/600/750mm; Operating pressure: 0.03 MPa | S11: Secondary Distribution / Compact Substations | T11: 1 | U11: Factory assembled, SF6 insulated, robotic welded tank; 30+ year service life | V11: 10
A12: 8 | B12: Lucy Electric | C12: Ring Main Unit (RMU) | D12: 3-Function Ring Main Unit (2x 630A Load Break Switches + 1x 630A Vacuum Circuit Breaker) - Outdoor | E12: Aegis Plus LLV 12kV IP54 | F12: Voltage: 12kV | G12: In (A): 630 | H12: Withstand: 21kA 3s | I12: Extensibility: Non-Extensible | J12: Ingress: IP54 (Outdoor) | K12: Complete Assembly | L12: Configured to Order | M12: AGP-NE-LLV-12kV-IP54 | O12: Upon request | P12: =IF(ISNUMBER(O12),O12*(1-N12),O12) | Q12: Aegis Plus | R12: Dimensions: 1050 x 715 x 1440 mm; Hermetically sealed SF6 stainless steel tank IP67; Peak withstand: 52.5kA; Lightning impulse: 75/125kV; Power freq: 28/50kV; Internal arc: IAC AF/AFL/AFLR 20kA 1s; DIN 400 Type C bushings; Bushing height: 450/600/750mm; Operating pressure: 0.03 MPa | S12: Secondary Distribution / Compact Substations | T12: 1 | U12: Factory assembled, SF6 insulated, robotic welded tank; 30+ year service life | V12: 10
A13: 9 | B13: Lucy Electric | C13: Ring Main Unit (RMU) | D13: 3-Function Ring Main Unit (2x 630A Load Break Switches + 1x 630A Vacuum Circuit Breaker) - Outdoor | E13: Aegis Plus LLV 24kV IP54 | F13: Voltage: 24kV | G13: In (A): 630 | H13: Withstand: 21kA 3s | I13: Extensibility: Non-Extensible | J13: Ingress: IP54 (Outdoor) | K13: Complete Assembly | L13: Configured to Order | M13: AGP-NE-LLV-24kV-IP54 | O13: Upon request | P13: =IF(ISNUMBER(O13),O13*(1-N13),O13) | Q13: Aegis Plus | R13: Dimensions: 1050 x 715 x 1440 mm; Hermetically sealed SF6 stainless steel tank IP67; Peak withstand: 52.5kA; Lightning impulse: 75/125kV; Power freq: 28/50kV; Internal arc: IAC AF/AFL/AFLR 20kA 1s; DIN 400 Type C bushings; Bushing height: 450/600/750mm; Operating pressure: 0.03 MPa | S13: Secondary Distribution / Compact Substations | T13: 1 | U13: Factory assembled, SF6 insulated, robotic welded tank; 30+ year service life | V13: 10
A14: 10 | B14: Lucy Electric | C14: Ring Main Unit (RMU) | D14: 3-Function Ring Main Unit (2x 630A Load Break Switches + 1x 250A Vacuum Circuit Breaker) | E14: Aegis Plus LLT 12kV IP41 | F14: Voltage: 12kV | G14: In (A): 630 | H14: Withstand: 21kA 3s | I14: Extensibility: Non-Extensible | J14: Ingress: IP41 (Indoor) | K14: Complete Assembly | L14: Configured to Order | M14: AGP-NE-LLT-12kV-IP41 | O14: Upon request | P14: =IF(ISNUMBER(O14),O14*(1-N14),O14) | Q14: Aegis Plus | R14: Dimensions: 1050 x 715 x 1430 mm; Hermetically sealed SF6 stainless steel tank IP67; Peak withstand: 52.5kA; Lightning impulse: 75/125kV; Power freq: 28/50kV; Internal arc: IAC AF/AFL/AFLR 20kA 1s; DIN 400 Type C bushings; Bushing height: 450/600/750mm; Operating pressure: 0.03 MPa | S14: Secondary Distribution / Compact Substations | T14: 1 | U14: Factory assembled, SF6 insulated, robotic welded tank; 30+ year service life | V14: 10
A15: 11 | B15: Lucy Electric | C15: Ring Main Unit (RMU) | D15: 3-Function Ring Main Unit (2x 630A Load Break Switches + 1x 250A Vacuum Circuit Breaker) | E15: Aegis Plus LLT 24kV IP41 | F15: Voltage: 24kV | G15: In (A): 630 | H15: Withstand: 21kA 3s | I15: Extensibility: Non-Extensible | J15: Ingress: IP41 (Indoor) | K15: Complete Assembly | L15: Configured to Order | M15: AGP-NE-LLT-24kV-IP41 | O15: Upon request | P15: =IF(ISNUMBER(O15),O15*(1-N15),O15) | Q15: Aegis Plus | R15: Dimensions: 1050 x 715 x 1430 mm; Hermetically sealed SF6 stainless steel tank IP67; Peak withstand: 52.5kA; Lightning impulse: 75/125kV; Power freq: 28/50kV; Internal arc: IAC AF/AFL/AFLR 20kA 1s; DIN 400 Type C bushings; Bushing height: 450/600/750mm; Operating pressure: 0.03 MPa | S15: Secondary Distribution / Compact Substations | T15: 1 | U15: Factory assembled, SF6 insulated, robotic welded tank; 30+ year service life | V15: 10
A16: 12 | B16: Lucy Electric | C16: Ring Main Unit (RMU) | D16: 3-Function Ring Main Unit (2x 630A Load Break Switches + 1x 630A Auto-Reclose VCB) | E16: Aegis Plus LLC 12kV IP41 | F16: Voltage: 12kV | G16: In (A): 630 | H16: Withstand: 21kA 3s | I16: Extensibility: Non-Extensible | J16: Ingress: IP41 (Indoor) | K16: Complete Assembly | L16: Configured to Order | M16: AGP-NE-LLC-12kV-IP41 | O16: Upon request | P16: =IF(ISNUMBER(O16),O16*(1-N16),O16) | Q16: Aegis Plus | R16: Dimensions: 1050 x 715 x 1430 mm; Hermetically sealed SF6 stainless steel tank IP67; Peak withstand: 52.5kA; Lightning impulse: 75/125kV; Power freq: 28/50kV; Internal arc: IAC AF/AFL/AFLR 20kA 1s; DIN 400 Type C bushings; Bushing height: 450/600/750mm; Operating pressure: 0.03 MPa | S16: Secondary Distribution / Compact Substations | T16: 1 | U16: Factory assembled, SF6 insulated, robotic welded tank; 30+ year service life | V16: 10
... A81: 77 | B81: Lucy Electric | C81: Instrument Transformers (CT/VT) | D81: Voltage Transformer Single-Phase 11000/110V Industrial Set of 3 | E81: VT 11000/110V Class 1.0 | F81: Ratio: 11000/110V | G81: Burden: 50VA | H81: Accuracy: Class 1.0 | I81: Configuration: 3x 1ph | J81: Standard: DIN 42600 | K81: Instrument Transformer | L81: Standard Stock | M81: VT-1P-11K-10 | O81: Upon request | P81: =IF(ISNUMBER(O81),O81*(1-N81),O81) | Q81: AMU VTs | R81: DIN 42600 narrow type standard; Epoxy resin cast; Primary voltage: 11kV / 22kV; Secondary voltage: 110V; Burden: 50VA; Class: Class 1.0 | S81: Aegis Plus Air Metering Units (Mt, M1, M2, M3) | T81: 3 | U81: Narrow profile for direct busbar/cable connection inside AMU | V81: 37
A82: 78 | B82: Lucy Electric | C82: Instrument Transformers (CT/VT) | D82: Current Transformer 50-25/1A Dual Ratio for AMU Metering | E82: CT 50-25/1A Class 0.2/0.5 | F82: Ratio: 50-25/1A | G82: Burden: 10VA | H82: Accuracy: Class 0.2/0.5 | I82: Mounting: Bushing / Busbar Mounted | J82: Quantity: Set of 3 | K82: Instrument Transformer | L82: Standard Stock | M82: CT-AMU-50-25-1A | O82: Upon request | P82: =IF(ISNUMBER(O82),O82*(1-N82),O82) | Q82: Protection & Metering CTs | R82: Ring type cast resin CT; Ratio: 50-25/1A; Burden: 10VA; Class: Class 0.2/0.5; Suitable for tariff metering or circuit breaker protection relay / TLF | S82: Aegis Plus VCB (V, T, C modules) & Air Metering Unit | T82: 3 pcs/set | U82: Conforms to IEC 61869-2; multi-ratio taps available | V82: 37
A83: 79 | B83: Lucy Electric | C83: Instrument Transformers (CT/VT) | D83: Current Transformer 50/25/5A Dual Ratio for AMU Metering | E83: CT 50/25/5A Class 0.5 | F83: Ratio: 50/25/5A | G83: Burden: 10VA | H83: Accuracy: Class 0.5 | I83: Mounting: Bushing / Busbar Mounted | J83: Quantity: Set of 3 | K83: Instrument Transformer | L83: Standard Stock | M83: CT-AMU-50-25-5A | O83: Upon request | P83: =IF(ISNUMBER(O83),O83*(1-N83),O83) | Q83: Protection & Metering CTs | R83: Ring type cast resin CT; Ratio: 50/25/5A; Burden: 10VA; Class: Class 0.5; Suitable for tariff metering or circuit breaker protection relay / TLF | S83: Aegis Plus VCB (V, T, C modules) & Air Metering Unit | T83: 3 pcs/set | U83: Conforms to IEC 61869-2; multi-ratio taps available | V83: 37
A84: 80 | B84: Lucy Electric | C84: Instrument Transformers (CT/VT) | D84: Current Transformer 100-50/1A Dual Ratio for AMU Metering | E84: CT 100-50/1A Class 0.2/0.5 | F84: Ratio: 100-50/1A | G84: Burden: 10VA | H84: Accuracy: Class 0.2/0.5 | I84: Mounting: Bushing / Busbar Mounted | J84: Quantity: Set of 3 | K84: Instrument Transformer | L84: Standard Stock | M84: CT-AMU-100-50-1A | O84: Upon request | P84: =IF(ISNUMBER(O84),O84*(1-N84),O84) | Q84: Protection & Metering CTs | R84: Ring type cast resin CT; Ratio: 100-50/1A; Burden: 10VA; Class: Class 0.2/0.5; Suitable for tariff metering or circuit breaker protection relay / TLF | S84: Aegis Plus VCB (V, T, C modules) & Air Metering Unit | T84: 3 pcs/set | U84: Conforms to IEC 61869-2; multi-ratio taps available | V84: 37
A85: 81 | B85: Lucy Electric | C85: Instrument Transformers (CT/VT) | D85: Current Transformer 100/50/5A Dual Ratio for AMU Metering | E85: CT 100/50/5A Class 0.5 | F85: Ratio: 100/50/5A | G85: Burden: 10/15VA | H85: Accuracy: Class 0.5 | I85: Mounting: Bushing / Busbar Mounted | J85: Quantity: Set of 3 | K85: Instrument Transformer | L85: Standard Stock | M85: CT-AMU-100-50-5A | O85: Upon request | P85: =IF(ISNUMBER(O85),O85*(1-N85),O85) | Q85: Protection & Metering CTs | R85: Ring type cast resin CT; Ratio: 100/50/5A; Burden: 10/15VA; Class: Class 0.5; Suitable for tariff metering or circuit breaker protection relay / TLF | S85: Aegis Plus VCB (V, T, C modules) & Air Metering Unit | T85: 3 pcs/set | U85: Conforms to IEC 61869-2; multi-ratio taps available | V85: 37
A86: 82 | B86: Lucy Electric | C86: Instrument Transformers (CT/VT) | D86: Current Transformer 200-100/1A Dual Ratio for AMU Metering | E86: CT 200-100/1A Class 0.2/0.5 | F86: Ratio: 200-100/1A | G86: Burden: 10/15VA | H86: Accuracy: Class 0.2/0.5 | I86: Mounting: Bushing / Busbar Mounted | J86: Quantity: Set of 3 | K86: Instrument Transformer | L86: Standard Stock | M86: CT-AMU-200-100-1A | O86: Upon request | P86: =IF(ISNUMBER(O86),O86*(1-N86),O86) | Q86: Protection & Metering CTs | R86: Ring type cast resin CT; Ratio: 200-100/1A; Burden: 10/15VA; Class: Class 0.2/0.5; Suitable for tariff metering or circuit breaker protection relay / TLF | S86: Aegis Plus VCB (V, T, C modules) & Air Metering Unit | T86: 3 pcs/set | U86: Conforms to IEC 61869-2; multi-ratio taps available | V86: 37
A87: 83 | B87: Lucy Electric | C87: Instrument Transformers (CT/VT) | D87: Current Transformer 200/100/5A Dual Ratio for AMU Metering | E87: CT 200/100/5A Class 0.5 | F87: Ratio: 200/100/5A | G87: Burden: 5/15VA | H87: Accuracy: Class 0.5 | I87: Mounting: Bushing / Busbar Mounted | J87: Quantity: Set of 3 | K87: Instrument Transformer | L87: Standard Stock | M87: CT-AMU-200-100-5A | O87: Upon request | P87: =IF(ISNUMBER(O87),O87*(1-N87),O87) | Q87: Protection & Metering CTs | R87: Ring type cast resin CT; Ratio: 200/100/5A; Burden: 5/15VA; Class: Class 0.5; Suitable for tariff metering or circuit breaker protection relay / TLF | S87: Aegis Plus VCB (V, T, C modules) & Air Metering Unit | T87: 3 pcs/set | U87: Conforms to IEC 61869-2; multi-ratio taps available | V87: 37
A88: 84 | B88: Lucy Electric | C88: Instrument Transformers (CT/VT) | D88: Current Transformer 300/150/5A Dual Ratio for AMU Metering | E88: CT 300/150/5A Class 0.5/1.0 | F88: Ratio: 300/150/5A | G88: Burden: 5/15VA | H88: Accuracy: Class 0.5/1.0 | I88: Mounting: Bushing / Busbar Mounted | J88: Quantity: Set of 3 | K88: Instrument Transformer | L88: Standard Stock | M88: CT-AMU-300-150-5A | O88: Upon request | P88: =IF(ISNUMBER(O88),O88*(1-N88),O88) | Q88: Protection & Metering CTs | R88: Ring type cast resin CT; Ratio: 300/150/5A; Burden: 5/15VA; Class: Class 0.5/1.0; Suitable for tariff metering or circuit breaker protection relay / TLF | S88: Aegis Plus VCB (V, T, C modules) & Air Metering Unit | T88: 3 pcs/set | U88: Conforms to IEC 61869-2; multi-ratio taps available | V88: 37
A89: 85 | B89: Lucy Electric | C89: Instrument Transformers (CT/VT) | D89: Current Transformer 400/200/5A Dual Ratio for AMU Metering | E89: CT 400/200/5A Class 0.2/0.5 | F89: Ratio: 400/200/5A | G89: Burden: 15/20VA | H89: Accuracy: Class 0.2/0.5 | I89: Mounting: Bushing / Busbar Mounted | J89: Quantity: Set of 3 | K89: Instrument Transformer | L89: Standard Stock | M89: CT-AMU-400-200-5A | O89: Upon request | P89: =IF(ISNUMBER(O89),O89*(1-N89),O89) | Q89: Protection & Metering CTs | R89: Ring type cast resin CT; Ratio: 400/200/5A; Burden: 15/20VA; Class: Class 0.2/0.5; Suitable for tariff metering or circuit breaker protection relay / TLF | S89: Aegis Plus VCB (V, T, C modules) & Air Metering Unit | T89: 3 pcs/set | U89: Conforms to IEC 61869-2; multi-ratio taps available | V89: 37
A90: 86 | B90: Lucy Electric | C90: Instrument Transformers (CT/VT) | D90: Protection Current Transformer Dual Primary Ratio 100:50/- | E90: CT 100:50/- 5P10 Protection | F90: Ratio: 100:50/- | G90: Burden: 15VA | H90: Accuracy: 5P10 Protection | I90: Mounting: Bushing / Busbar Mounted | J90: Quantity: Set of 3 | K90: Instrument Transformer | L90: Standard Stock | M90: CT-PROT-100-50 | O90: Upon request | P90: =IF(ISNUMBER(O90),O90*(1-N90),O90) | Q90: Protection & Metering CTs | R90: Ring type cast resin CT; Ratio: 100:50/-; Burden: 15VA; Class: 5P10 Protection; Suitable for tariff metering or circuit breaker protection relay / TLF | S90: Aegis Plus VCB (V, T, C modules) & Air Metering Unit | T90: 3 pcs/set | U90: Conforms to IEC 61869-2; multi-ratio taps available | V90: 46
A91: 87 | B91: Lucy Electric | C91: Instrument Transformers (CT/VT) | D91: Protection Current Transformer Dual Primary Ratio 200:100/- | E91: CT 200:100/- 5P10 Protection | F91: Ratio: 200:100/- | G91: Burden: 15VA | H91: Accuracy: 5P10 Protection | I91: Mounting: Bushing / Busbar Mounted | J91: Quantity: Set of 3 | K91: Instrument Transformer | L91: Standard Stock | M91: CT-PROT-200-100 | O91: Upon request | P91: =IF(ISNUMBER(O91),O91*(1-N91),O91) | Q91: Protection & Metering CTs | R91: Ring type cast resin CT; Ratio: 200:100/-; Burden: 15VA; Class: 5P10 Protection; Suitable for tariff metering or circuit breaker protection relay / TLF | S91: Aegis Plus VCB (V, T, C modules) & Air Metering Unit | T91: 3 pcs/set | U91: Conforms to IEC 61869-2; multi-ratio taps available | V91: 46
A92: 88 | B92: Lucy Electric | C92: Instrument Transformers (CT/VT) | D92: Protection Current Transformer Triple Primary Ratio 150:100:50/- | E92: CT 150:100:50/- 5P10 Protection | F92: Ratio: 150:100:50/- | G92: Burden: 15VA | H92: Accuracy: 5P10 Protection | I92: Mounting: Bushing / Busbar Mounted | J92: Quantity: Set of 3 | K92: Instrument Transformer | L92: Standard Stock | M92: CT-PROT-150-100-50 | O92: Upon request | P92: =IF(ISNUMBER(O92),O92*(1-N92),O92) | Q92: Protection & Metering CTs | R92: Ring type cast resin CT; Ratio: 150:100:50/-; Burden: 15VA; Class: 5P10 Protection; Suitable for tariff metering or circuit breaker protection relay / TLF | S92: Aegis Plus VCB (V, T, C modules) & Air Metering Unit | T92: 3 pcs/set | U92: Conforms to IEC 61869-2; multi-ratio taps available | V92: 46
A93: 89 | B93: Lucy Electric | C93: Smart Grid RTU & Automation | D93: Gemini 3 Modular Remote Terminal Unit (RTU) Complete Base Unit | E93: Gemini 3 G3-RTU-BASE | F93: Power: 24V DC | G93: Capacity: 7000 events | H93: Protocol: Modbus / DNP3 / IEC101/104 | I93: Mounting: Integrated LV Compartment | J93: Environment: Maintenance Free | K93: RTU Module | L93: Standard Stock | M93: G3-RTU-BASE | O93: Upon request | P93: =IF(ISNUMBER(O93),O93*(1-N93),O93) | Q93: Gemini 3 | R93: Communication: Dual isolated Ethernet, RS232, isolated RS485; GSM/GPRS/Radio/Optic fibre ready; 7000 event non-volatile memory; SCADA synchronised real-time clock; ENATS compliant | S93: Aegis Plus Ring Main Units (Upper LV compartment integration) | T93: 1 | U93: Factory fitted neatly in upper LV compartment, eliminating external control boxes | V93: 38
A94: 90 | B94: Lucy Electric | C94: Smart Grid RTU & Automation | D94: Gemini 3 Master Control Module (Main Processor & Protocol Communications) | E94: Gemini 3 G3-MCM | F94: Power: 24V DC | G94: Capacity: Dual Eth / RS232 / RS485 | H94: Protocol: IEC 60870-5-104/101, DNP 3.0 | I94: Mounting: Modular Plug-in | J94: Environment: Maintenance Free | K94: RTU Module | L94: Standard Stock | M94: G3-MCM | O94: Upon request | P94: =IF(ISNUMBER(O94),O94*(1-N94),O94) | Q94: Gemini 3 | R94: Communication: Dual isolated Ethernet, RS232, isolated RS485; GSM/GPRS/Radio/Optic fibre ready; 7000 event non-volatile memory; SCADA synchronised real-time clock; ENATS compliant | S94: Aegis Plus Ring Main Units (Upper LV compartment integration) | T94: 1 | U94: Factory fitted neatly in upper LV compartment, eliminating external control boxes | V94: 38
A95: 91 | B95: Lucy Electric | C95: Smart Grid RTU & Automation | D95: Gemini 3 Single Switch Module (Secure interlocked control of single switch) | E95: Gemini 3 G3-SSM | F95: Power: 24V DC | G95: Capacity: 1 Switch Control | H95: Protocol: Interlocked Control | I95: Mounting: Modular Plug-in | J95: Environment: Maintenance Free | K95: RTU Module | L95: Standard Stock | M95: G3-SSM | O95: Upon request | P95: =IF(ISNUMBER(O95),O95*(1-N95),O95) | Q95: Gemini 3 | R95: Communication: Dual isolated Ethernet, RS232, isolated RS485; GSM/GPRS/Radio/Optic fibre ready; 7000 event non-volatile memory; SCADA synchronised real-time clock; ENATS compliant | S95: Aegis Plus Ring Main Units (Upper LV compartment integration) | T95: 1 | U95: Factory fitted neatly in upper LV compartment, eliminating external control boxes | V95: 38
A96: 92 | B96: Lucy Electric | C96: Smart Grid RTU & Automation | D96: Gemini 3 Dual Switch Module (Secure interlocked control of two MV switches) | E96: Gemini 3 G3-DSM | F96: Power: 24V DC | G96: Capacity: 2 Switch Control | H96: Protocol: Interlocked Control | I96: Mounting: Modular Plug-in | J96: Environment: Maintenance Free | K96: RTU Module | L96: Standard Stock | M96: G3-DSM | O96: Upon request | P96: =IF(ISNUMBER(O96),O96*(1-N96),O96) | Q96: Gemini 3 | R96: Communication: Dual isolated Ethernet, RS232, isolated RS485; GSM/GPRS/Radio/Optic fibre ready; 7000 event non-volatile memory; SCADA synchronised real-time clock; ENATS compliant | S96: Aegis Plus Ring Main Units (Upper LV compartment integration) | T96: 1 | U96: Factory fitted neatly in upper LV compartment, eliminating external control boxes | V96: 38
A97: 93 | B97: Lucy Electric | C97: Smart Grid RTU & Automation | D97: Gemini 3 Power Supply Module with intelligent 24V DC battery charging | E97: Gemini 3 G3-PSM | F97: Power: 110-240V AC / 24V DC | G97: Capacity: Intelligent Charger | H97: Protocol: Regulated Power Supply | I97: Mounting: Modular Plug-in | J97: Environment: Maintenance Free | K97: RTU Module | L97: Standard Stock | M97: G3-PSM | O97: Upon request | P97: =IF(ISNUMBER(O97),O97*(1-N97),O97) | Q97: Gemini 3 | R97: Communication: Dual isolated Ethernet, RS232, isolated RS485; GSM/GPRS/Radio/Optic fibre ready; 7000 event non-volatile memory; SCADA synchronised real-time clock; ENATS compliant | S97: Aegis Plus Ring Main Units (Upper LV compartment integration) | T97: 1 | U97: Factory fitted neatly in upper LV compartment, eliminating external control boxes | V97: 38
A98: 94 | B98: Lucy Electric | C98: Smart Grid RTU & Automation | D98: Gemini 3 Input Output Module (Digital & analogue inputs, relay outputs) | E98: Gemini 3 G3-IOM | F98: Power: 24V DC | G98: Capacity: Multi I/O | H98: Protocol: Status & Alarms | I98: Mounting: Modular Plug-in | J98: Environment: Maintenance Free | K98: RTU Module | L98: Standard Stock | M98: G3-IOM | O98: Upon request | P98: =IF(ISNUMBER(O98),O98*(1-N98),O98) | Q98: Gemini 3 | R98: Communication: Dual isolated Ethernet, RS232, isolated RS485; GSM/GPRS/Radio/Optic fibre ready; 7000 event non-volatile memory; SCADA synchronised real-time clock; ENATS compliant | S98: Aegis Plus Ring Main Units (Upper LV compartment integration) | T98: 1 | U98: Factory fitted neatly in upper LV compartment, eliminating external control boxes | V98: 38
A99: 95 | B99: Lucy Electric | C99: Smart Grid RTU & Automation | D99: Gemini 3 Fault Passage Module (Dual FPI overcurrent & earth fault detection) | E99: Gemini 3 G3-FPM | F99: Power: 24V DC | G99: Capacity: Dual FPI | H99: Protocol: Overcurrent & Earth Fault | I99: Mounting: Modular Plug-in | J99: Environment: Maintenance Free | K99: RTU Module | L99: Standard Stock | M99: G3-FPM | O99: Upon request | P99: =IF(ISNUMBER(O99),O99*(1-N99),O99) | Q99: Gemini 3 | R99: Communication: Dual isolated Ethernet, RS232, isolated RS485; GSM/GPRS/Radio/Optic fibre ready; 7000 event non-volatile memory; SCADA synchronised real-time clock; ENATS compliant | S99: Aegis Plus Ring Main Units (Upper LV compartment integration) | T99: 1 | U99: Factory fitted neatly in upper LV compartment, eliminating external control boxes | V99: 38
A100: 96 | B100: Lucy Electric | C100: Smart Grid RTU & Automation | D100: Gemini 3 Human Machine Interface (Local LCD display and push-button control) | E100: Gemini 3 G3-HMI | F100: Power: 24V DC | G100: Capacity: LCD Display | H100: Protocol: Security Enabled Local Control | I100: Mounting: Fascia Mounted | J100: Environment: Maintenance Free | K100: RTU Module | L100: Standard Stock | M100: G3-HMI | O100: Upon request | P100: =IF(ISNUMBER(O100),O100*(1-N100),O100) | Q100: Gemini 3 | R100: Communication: Dual isolated Ethernet, RS232, isolated RS485; GSM/GPRS/Radio/Optic fibre ready; 7000 event non-volatile memory; SCADA synchronised real-time clock; ENATS compliant | S100: Aegis Plus Ring Main Units (Upper LV compartment integration) | T100: 1 | U100: Factory fitted neatly in upper LV compartment, eliminating external control boxes | V100: 38
A101: 97 | B101: Lucy Electric | C101: Smart Grid RTU & Automation | D101: Automatic Transfer Scheme (ATS) Automation Package with Gemini 3 RTU | E101: Gemini 3 AGP-ATS-PACKAGE | F101: Power: 24V DC / Mains | G101: Capacity: Dual Incomer Auto Changeover | H101: Protocol: Fast Auto-Sectionalising | I101: Mounting: Upper LV Enclosure | J101: Environment: Maintenance Free | K101: RTU Module | L101: Standard Stock | M101: AGP-ATS-PACKAGE | O101: Upon request | P101: =IF(ISNUMBER(O101),O101*(1-N101),O101) | Q101: Gemini 3 | R101: Communication: Dual isolated Ethernet, RS232, isolated RS485; GSM/GPRS/Radio/Optic fibre ready; 7000 event non-volatile memory; SCADA synchronised real-time clock; ENATS compliant | S101: Aegis Plus Ring Main Units (Upper LV compartment integration) | T101: 1 | U101: Factory fitted neatly in upper LV compartment, eliminating external control boxes | V101: 39
A102: 98 | B102: Lucy Electric | C102: Circuit Breaker Protection (TLF) | D102: Time Limit Fuse Link 3A (57mm x 13mm) for Transformer Fault Protection | E102: Fuse Link 3A | F102: Current: 3A | G102: Voltage: 3.3 - 24kV | H102: Transformer: Up to 2000kVA | I102: Dimensions: 57mm x 13mm | J102: Location: LV Compartment | K102: Protection Fuse Link | L102: Stocked | M102: TLF-3A | O102: 5 | P102: =IF(ISNUMBER(O102),O102*(1-N102),O102) | Q102: Aegis Protection | R102: Fuse dimensions: Length 57mm x Diameter 13mm; Shunted with circuit breaker trip coil fed from CT; Zero capacitor charging time lag; Overcurrent & earth fault protection; Standards: ENA TS 12-6, ENA TS 41-36 | S102: Aegis Plus VCB (V and T modules) & F switch | T102: 3 | U102: Cost-effective transformer fault protection; Approximate replacement cost: $5.00 | V102: 23
A103: 99 | B103: Lucy Electric | C103: Circuit Breaker Protection (TLF) | D103: Time Limit Fuse Link 5A (57mm x 13mm) for Transformer Fault Protection | E103: Fuse Link 5A | F103: Current: 5A | G103: Voltage: 3.3 - 24kV | H103: Transformer: Up to 2000kVA | I103: Dimensions: 57mm x 13mm | J103: Location: LV Compartment | K103: Protection Fuse Link | L103: Stocked | M103: TLF-5A | O103: 5 | P103: =IF(ISNUMBER(O103),O103*(1-N103),O103) | Q103: Aegis Protection | R103: Fuse dimensions: Length 57mm x Diameter 13mm; Shunted with circuit breaker trip coil fed from CT; Zero capacitor charging time lag; Overcurrent & earth fault protection; Standards: ENA TS 12-6, ENA TS 41-36 | S103: Aegis Plus VCB (V and T modules) & F switch | T103: 3 | U103: Cost-effective transformer fault protection; Approximate replacement cost: $5.00 | V103: 23
A104: 100 | B104: Lucy Electric | C104: Circuit Breaker Protection (TLF) | D104: Time Limit Fuse Link 7.5A (57mm x 13mm) for Transformer Fault Protection | E104: Fuse Link 7.5A | F104: Current: 7.5A | G104: Voltage: 3.3 - 24kV | H104: Transformer: Up to 2000kVA | I104: Dimensions: 57mm x 13mm | J104: Location: LV Compartment | K104: Protection Fuse Link | L104: Stocked | M104: TLF-7.5A | O104: 5 | P104: =IF(ISNUMBER(O104),O104*(1-N104),O104) | Q104: Aegis Protection | R104: Fuse dimensions: Length 57mm x Diameter 13mm; Shunted with circuit breaker trip coil fed from CT; Zero capacitor charging time lag; Overcurrent & earth fault protection; Standards: ENA TS 12-6, ENA TS 41-36 | S104: Aegis Plus VCB (V and T modules) & F switch | T104: 3 | U104: Cost-effective transformer fault protection; Approximate replacement cost: $5.00 | V104: 23
A105: 101 | B105: Lucy Electric | C105: Circuit Breaker Protection (TLF) | D105: Time Limit Fuse Link 10A (57mm x 13mm) for Transformer Fault Protection | E105: Fuse Link 10A | F105: Current: 10A | G105: Voltage: 3.3 - 24kV | H105: Transformer: Up to 2000kVA | I105: Dimensions: 57mm x 13mm | J105: Location: LV Compartment | K105: Protection Fuse Link | L105: Stocked | M105: TLF-10A | O105: 5 | P105: =IF(ISNUMBER(O105),O105*(1-N105),O105) | Q105: Aegis Protection | R105: Fuse dimensions: Length 57mm x Diameter 13mm; Shunted with circuit breaker trip coil fed from CT; Zero capacitor charging time lag; Overcurrent & earth fault protection; Standards: ENA TS 12-6, ENA TS 41-36 | S105: Aegis Plus VCB (V and T modules) & F switch | T105: 3 | U105: Cost-effective transformer fault protection; Approximate replacement cost: $5.00 | V105: 23
...

Sheet E-Commerce & Catalogue Schema
A1: Lucy Electric Aegis Plus - E-Commerce & Product Master Data
A2: Clean, normalized tabular data ready for ERP, E-Commerce, PIM import, and parametric filtering.
A4: Category | B4: Subcategory | C4: Product Family | D4: Product Code / SKU | E4: Product Name | F4: Description | G4: Voltage Rating (kV) | H4: Current Rating (A) | I4: Breaking / Withstand Capacity (kA) | J4: Dimensions (W x D x H mm) | K4: Ingress Protection (IP) | L4: Technical Specifications | M4: Currency | N4: List Price | O4: Discount (%) | P4: Net Price | Q4: Price Status | R4: Availability / Lead Time Details | S4: Installation / Mounting Type | T4: Standards / Compliance | U4: Catalogue Page Reference
A5: Ring Main Unit (RMU) | B5: Non-Extensible Secondary Switchgear | C5: Aegis Plus | D5: AGP-NE-LLF-12kV-IP41 | E5: Aegis Plus LLF 12kV IP41 | F5: 3-Function Ring Main Unit (2x 630A Load Break Switches + 1x 200A Switch Fuse) | G5: 12kV | H5: 630A | I5: 21kA 3s | J5: 1050 x 785 x 1430 mm | K5: IP41 (Indoor) | L5: Dimensions: 1050 x 785 x 1430 mm; Hermetically sealed SF6 stainless steel tank IP67; Peak withstand: 52.5kA; Lightning impulse: 75/125kV; Power freq: 28/50kV; Internal arc: IAC AF/AFL/AFLR 20kA 1s; DIN 400 Type C bushings; Bushing height: 450/600/750mm; Operating pressure: 0.03 MPa | M5: USD / Upon Request | N5: Upon request | P5: =IF(ISNUMBER(N5),N5*(1-O5),N5) | Q5: Upon request | R5: Manufactured to order (6-12 weeks) | S5: Floor Ground / Substation Plinth | T5: IEC 62271-100, IEC 62271-102, IEC 62271-103, IEC 62271-200 | U5: Page 10
A6: Ring Main Unit (RMU) | B6: Non-Extensible Secondary Switchgear | C6: Aegis Plus | D6: AGP-NE-LLF-24kV-IP41 | E6: Aegis Plus LLF 24kV IP41 | F6: 3-Function Ring Main Unit (2x 630A Load Break Switches + 1x 200A Switch Fuse) | G6: 24kV | H6: 630A | I6: 21kA 3s | J6: 1050 x 785 x 1430 mm | K6: IP41 (Indoor) | L6: Dimensions: 1050 x 785 x 1430 mm; Hermetically sealed SF6 stainless steel tank IP67; Peak withstand: 52.5kA; Lightning impulse: 75/125kV; Power freq: 28/50kV; Internal arc: IAC AF/AFL/AFLR 20kA 1s; DIN 400 Type C bushings; Bushing height: 450/600/750mm; Operating pressure: 0.03 MPa | M6: USD / Upon Request | N6: Upon request | P6: =IF(ISNUMBER(N6),N6*(1-O6),N6) | Q6: Upon request | R6: Manufactured to order (6-12 weeks) | S6: Floor Ground / Substation Plinth | T6: IEC 62271-100, IEC 62271-102, IEC 62271-103, IEC 62271-200 | U6: Page 10
A7: Ring Main Unit (RMU) | B7: Non-Extensible Secondary Switchgear | C7: Aegis Plus | D7: AGP-NE-LLF-12kV-IP54 | E7: Aegis Plus LLF 12kV IP54 | F7: 3-Function Ring Main Unit (2x 630A Load Break Switches + 1x 200A Switch Fuse) - Outdoor | G7: 12kV | H7: 630A | I7: 21kA 3s | J7: 1050 x 785 x 1440 mm | K7: IP54 (Outdoor) | L7: Dimensions: 1050 x 785 x 1440 mm; Hermetically sealed SF6 stainless steel tank IP67; Peak withstand: 52.5kA; Lightning impulse: 75/125kV; Power freq: 28/50kV; Internal arc: IAC AF/AFL/AFLR 20kA 1s; DIN 400 Type C bushings; Bushing height: 450/600/750mm; Operating pressure: 0.03 MPa | M7: USD / Upon Request | N7: Upon request | P7: =IF(ISNUMBER(N7),N7*(1-O7),N7) | Q7: Upon request | R7: Manufactured to order (6-12 weeks) | S7: Floor Ground / Substation Plinth | T7: IEC 62271-100, IEC 62271-102, IEC 62271-103, IEC 62271-200 | U7: Page 10
A8: Ring Main Unit (RMU) | B8: Non-Extensible Secondary Switchgear | C8: Aegis Plus | D8: AGP-NE-LLF-24kV-IP54 | E8: Aegis Plus LLF 24kV IP54 | F8: 3-Function Ring Main Unit (2x 630A Load Break Switches + 1x 200A Switch Fuse) - Outdoor | G8: 24kV | H8: 630A | I8: 21kA 3s | J8: 1050 x 785 x 1440 mm | K8: IP54 (Outdoor) | L8: Dimensions: 1050 x 785 x 1440 mm; Hermetically sealed SF6 stainless steel tank IP67; Peak withstand: 52.5kA; Lightning impulse: 75/125kV; Power freq: 28/50kV; Internal arc: IAC AF/AFL/AFLR 20kA 1s; DIN 400 Type C bushings; Bushing height: 450/600/750mm; Operating pressure: 0.03 MPa | M8: USD / Upon Request | N8: Upon request | P8: =IF(ISNUMBER(N8),N8*(1-O8),N8) | Q8: Upon request | R8: Manufactured to order (6-12 weeks) | S8: Floor Ground / Substation Plinth | T8: IEC 62271-100, IEC 62271-102, IEC 62271-103, IEC 62271-200 | U8: Page 10
A9: Ring Main Unit (RMU) | B9: Non-Extensible Secondary Switchgear | C9: Aegis Plus | D9: AGP-NE-LLV-12kV-IP41 | E9: Aegis Plus LLV 12kV IP41 | F9: 3-Function Ring Main Unit (2x 630A Load Break Switches + 1x 630A Vacuum Circuit Breaker) | G9: 12kV | H9: 630A | I9: 21kA 3s | J9: 1050 x 715 x 1430 mm | K9: IP41 (Indoor) | L9: Dimensions: 1050 x 715 x 1430 mm; Hermetically sealed SF6 stainless steel tank IP67; Peak withstand: 52.5kA; Lightning impulse: 75/125kV; Power freq: 28/50kV; Internal arc: IAC AF/AFL/AFLR 20kA 1s; DIN 400 Type C bushings; Bushing height: 450/600/750mm; Operating pressure: 0.03 MPa | M9: USD / Upon Request | N9: Upon request | P9: =IF(ISNUMBER(N9),N9*(1-O9),N9) | Q9: Upon request | R9: Manufactured to order (6-12 weeks) | S9: Floor Ground / Substation Plinth | T9: IEC 62271-100, IEC 62271-102, IEC 62271-103, IEC 62271-200 | U9: Page 10
A10: Ring Main Unit (RMU) | B10: Non-Extensible Secondary Switchgear | C10: Aegis Plus | D10: AGP-NE-LLV-17.5kV-IP41 | E10: Aegis Plus LLV 17.5kV IP41 | F10: 3-Function Ring Main Unit (2x 630A Load Break Switches + 1x 630A Vacuum Circuit Breaker) | G10: 17.5kV | H10: 630A | I10: 21kA 3s | J10: 1050 x 715 x 1430 mm | K10: IP41 (Indoor) | L10: Dimensions: 1050 x 715 x 1430 mm; Hermetically sealed SF6 stainless steel tank IP67; Peak withstand: 52.5kA; Lightning impulse: 75/125kV; Power freq: 28/50kV; Internal arc: IAC AF/AFL/AFLR 20kA 1s; DIN 400 Type C bushings; Bushing height: 450/600/750mm; Operating pressure: 0.03 MPa | M10: USD / Upon Request | N10: Upon request | P10: =IF(ISNUMBER(N10),N10*(1-O10),N10) | Q10: Upon request | R10: Manufactured to order (6-12 weeks) | S10: Floor Ground / Substation Plinth | T10: IEC 62271-100, IEC 62271-102, IEC 62271-103, IEC 62271-200 | U10: Page 10
A11: Ring Main Unit (RMU) | B11: Non-Extensible Secondary Switchgear | C11: Aegis Plus | D11: AGP-NE-LLV-24kV-IP41 | E11: Aegis Plus LLV 24kV IP41 | F11: 3-Function Ring Main Unit (2x 630A Load Break Switches + 1x 630A Vacuum Circuit Breaker) | G11: 24kV | H11: 630A | I11: 21kA 3s | J11: 1050 x 715 x 1430 mm | K11: IP41 (Indoor) | L11: Dimensions: 1050 x 715 x 1430 mm; Hermetically sealed SF6 stainless steel tank IP67; Peak withstand: 52.5kA; Lightning impulse: 75/125kV; Power freq: 28/50kV; Internal arc: IAC AF/AFL/AFLR 20kA 1s; DIN 400 Type C bushings; Bushing height: 450/600/750mm; Operating pressure: 0.03 MPa | M11: USD / Upon Request | N11: Upon request | P11: =IF(ISNUMBER(N11),N11*(1-O11),N11) | Q11: Upon request | R11: Manufactured to order (6-12 weeks) | S11: Floor Ground / Substation Plinth | T11: IEC 62271-100, IEC 62271-102, IEC 62271-103, IEC 62271-200 | U11: Page 10
A12: Ring Main Unit (RMU) | B12: Non-Extensible Secondary Switchgear | C12: Aegis Plus | D12: AGP-NE-LLV-12kV-IP54 | E12: Aegis Plus LLV 12kV IP54 | F12: 3-Function Ring Main Unit (2x 630A Load Break Switches + 1x 630A Vacuum Circuit Breaker) - Outdoor | G12: 12kV | H12: 630A | I12: 21kA 3s | J12: 1050 x 715 x 1440 mm | K12: IP54 (Outdoor) | L12: Dimensions: 1050 x 715 x 1440 mm; Hermetically sealed SF6 stainless steel tank IP67; Peak withstand: 52.5kA; Lightning impulse: 75/125kV; Power freq: 28/50kV; Internal arc: IAC AF/AFL/AFLR 20kA 1s; DIN 400 Type C bushings; Bushing height: 450/600/750mm; Operating pressure: 0.03 MPa | M12: USD / Upon Request | N12: Upon request | P12: =IF(ISNUMBER(N12),N12*(1-O12),N12) | Q12: Upon request | R12: Manufactured to order (6-12 weeks) | S12: Floor Ground / Substation Plinth | T12: IEC 62271-100, IEC 62271-102, IEC 62271-103, IEC 62271-200 | U12: Page 10
A13: Ring Main Unit (RMU) | B13: Non-Extensible Secondary Switchgear | C13: Aegis Plus | D13: AGP-NE-LLV-24kV-IP54 | E13: Aegis Plus LLV 24kV IP54 | F13: 3-Function Ring Main Unit (2x 630A Load Break Switches + 1x 630A Vacuum Circuit Breaker) - Outdoor | G13: 24kV | H13: 630A | I13: 21kA 3s | J13: 1050 x 715 x 1440 mm | K13: IP54 (Outdoor) | L13: Dimensions: 1050 x 715 x 1440 mm; Hermetically sealed SF6 stainless steel tank IP67; Peak withstand: 52.5kA; Lightning impulse: 75/125kV; Power freq: 28/50kV; Internal arc: IAC AF/AFL/AFLR 20kA 1s; DIN 400 Type C bushings; Bushing height: 450/600/750mm; Operating pressure: 0.03 MPa | M13: USD / Upon Request | N13: Upon request | P13: =IF(ISNUMBER(N13),N13*(1-O13),N13) | Q13: Upon request | R13: Manufactured to order (6-12 weeks) | S13: Floor Ground / Substation Plinth | T13: IEC 62271-100, IEC 62271-102, IEC 62271-103, IEC 62271-200 | U13: Page 10
A14: Ring Main Unit (RMU) | B14: Non-Extensible Secondary Switchgear | C14: Aegis Plus | D14: AGP-NE-LLT-12kV-IP41 | E14: Aegis Plus LLT 12kV IP41 | F14: 3-Function Ring Main Unit (2x 630A Load Break Switches + 1x 250A Vacuum Circuit Breaker) | G14: 12kV | H14: 630A | I14: 21kA 3s | J14: 1050 x 715 x 1430 mm | K14: IP41 (Indoor) | L14: Dimensions: 1050 x 715 x 1430 mm; Hermetically sealed SF6 stainless steel tank IP67; Peak withstand: 52.5kA; Lightning impulse: 75/125kV; Power freq: 28/50kV; Internal arc: IAC AF/AFL/AFLR 20kA 1s; DIN 400 Type C bushings; Bushing height: 450/600/750mm; Operating pressure: 0.03 MPa | M14: USD / Upon Request | N14: Upon request | P14: =IF(ISNUMBER(N14),N14*(1-O14),N14) | Q14: Upon request | R14: Manufactured to order (6-12 weeks) | S14: Floor Ground / Substation Plinth | T14: IEC 62271-100, IEC 62271-102, IEC 62271-103, IEC 62271-200 | U14: Page 10
A15: Ring Main Unit (RMU) | B15: Non-Extensible Secondary Switchgear | C15: Aegis Plus | D15: AGP-NE-LLT-24kV-IP41 | E15: Aegis Plus LLT 24kV IP41 | F15: 3-Function Ring Main Unit (2x 630A Load Break Switches + 1x 250A Vacuum Circuit Breaker) | G15: 24kV | H15: 630A | I15: 21kA 3s | J15: 1050 x 715 x 1430 mm | K15: IP41 (Indoor) | L15: Dimensions: 1050 x 715 x 1430 mm; Hermetically sealed SF6 stainless steel tank IP67; Peak withstand: 52.5kA; Lightning impulse: 75/125kV; Power freq: 28/50kV; Internal arc: IAC AF/AFL/AFLR 20kA 1s; DIN 400 Type C bushings; Bushing height: 450/600/750mm; Operating pressure: 0.03 MPa | M15: USD / Upon Request | N15: Upon request | P15: =IF(ISNUMBER(N15),N15*(1-O15),N15) | Q15: Upon request | R15: Manufactured to order (6-12 weeks) | S15: Floor Ground / Substation Plinth | T15: IEC 62271-100, IEC 62271-102, IEC 62271-103, IEC 62271-200 | U15: Page 10
A16: Ring Main Unit (RMU) | B16: Non-Extensible Secondary Switchgear | C16: Aegis Plus | D16: AGP-NE-LLC-12kV-IP41 | E16: Aegis Plus LLC 12kV IP41 | F16: 3-Function Ring Main Unit (2x 630A Load Break Switches + 1x 630A Auto-Reclose VCB) | G16: 12kV | H16: 630A | I16: 21kA 3s | J16: 1050 x 715 x 1430 mm | K16: IP41 (Indoor) | L16: Dimensions: 1050 x 715 x 1430 mm; Hermetically sealed SF6 stainless steel tank IP67; Peak withstand: 52.5kA; Lightning impulse: 75/125kV; Power freq: 28/50kV; Internal arc: IAC AF/AFL/AFLR 20kA 1s; DIN 400 Type C bushings; Bushing height: 450/600/750mm; Operating pressure: 0.03 MPa | M16: USD / Upon Request | N16: Upon request | P16: =IF(ISNUMBER(N16),N16*(1-O16),N16) | Q16: Upon request | R16: Manufactured to order (6-12 weeks) | S16: Floor Ground / Substation Plinth | T16: IEC 62271-100, IEC 62271-102, IEC 62271-103, IEC 62271-200 | U16: Page 10
... A101: Smart Grid RTU & Automation | B101: Remote Terminal Units (RTU) | C101: Gemini 3 | D101: AGP-ATS-PACKAGE | E101: Gemini 3 AGP-ATS-PACKAGE | F101: Automatic Transfer Scheme (ATS) Automation Package with Gemini 3 RTU | G101: 24V DC / Mains | H101: - | I101: - | J101: Integrated Upper LV compartment | K101: IP41 / IP54 Enclosure | L101: Communication: Dual isolated Ethernet, RS232, isolated RS485; GSM/GPRS/Radio/Optic fibre ready; 7000 event non-volatile memory; SCADA synchronised real-time clock; ENATS compliant | M101: USD / Upon Request | N101: Upon request | P101: =IF(ISNUMBER(N101),N101*(1-O101),N101) | Q101: Upon request | R101: Available to order (2-4 weeks) | S101: Integrated Upper LV Compartment | T101: ENATS, IEC 60870-5-101/104, DNP 3.0, Modbus TCP/RTU | U101: Page 39
A102: Circuit Breaker Protection (TLF) | B102: Protection Fuses & Links | C102: Aegis Protection | D102: TLF-3A | E102: Fuse Link 3A | F102: Time Limit Fuse Link 3A (57mm x 13mm) for Transformer Fault Protection | G102: 3.3 - 24kV | H102: 3A | I102: Fast trip via shunt coil | J102: 57mm x 13mm | K102: IP41 (Internal) | L102: Fuse dimensions: Length 57mm x Diameter 13mm; Shunted with circuit breaker trip coil fed from CT; Zero capacitor charging time lag; Overcurrent & earth fault protection; Standards: ENA TS 12-6, ENA TS 41-36 | M102: USD | N102: 5 | P102: =IF(ISNUMBER(N102),N102*(1-O102),N102) | Q102: Quoted in Catalogue | R102: In Stock (Immediate Dispatch) | S102: Fuse Clips in Front LV Panel | T102: ENA TS 12-6, ENA TS 41-36, IEC 62271-105 | U102: Page 23
A103: Circuit Breaker Protection (TLF) | B103: Protection Fuses & Links | C103: Aegis Protection | D103: TLF-5A | E103: Fuse Link 5A | F103: Time Limit Fuse Link 5A (57mm x 13mm) for Transformer Fault Protection | G103: 3.3 - 24kV | H103: 5A | I103: Fast trip via shunt coil | J103: 57mm x 13mm | K103: IP41 (Internal) | L103: Fuse dimensions: Length 57mm x Diameter 13mm; Shunted with circuit breaker trip coil fed from CT; Zero capacitor charging time lag; Overcurrent & earth fault protection; Standards: ENA TS 12-6, ENA TS 41-36 | M103: USD | N103: 5 | P103: =IF(ISNUMBER(N103),N103*(1-O103),N103) | Q103: Quoted in Catalogue | R103: In Stock (Immediate Dispatch) | S103: Fuse Clips in Front LV Panel | T103: ENA TS 12-6, ENA TS 41-36, IEC 62271-105 | U103: Page 23
A104: Circuit Breaker Protection (TLF) | B104: Protection Fuses & Links | C104: Aegis Protection | D104: TLF-7.5A | E104: Fuse Link 7.5A | F104: Time Limit Fuse Link 7.5A (57mm x 13mm) for Transformer Fault Protection | G104: 3.3 - 24kV | H104: 7.5A | I104: Fast trip via shunt coil | J104: 57mm x 13mm | K104: IP41 (Internal) | L104: Fuse dimensions: Length 57mm x Diameter 13mm; Shunted with circuit breaker trip coil fed from CT; Zero capacitor charging time lag; Overcurrent & earth fault protection; Standards: ENA TS 12-6, ENA TS 41-36 | M104: USD | N104: 5 | P104: =IF(ISNUMBER(N104),N104*(1-O104),N104) | Q104: Quoted in Catalogue | R104: In Stock (Immediate Dispatch) | S104: Fuse Clips in Front LV Panel | T104: ENA TS 12-6, ENA TS 41-36, IEC 62271-105 | U104: Page 23
A105: Circuit Breaker Protection (TLF) | B105: Protection Fuses & Links | C105: Aegis Protection | D105: TLF-10A | E105: Fuse Link 10A | F105: Time Limit Fuse Link 10A (57mm x 13mm) for Transformer Fault Protection | G105: 3.3 - 24kV | H105: 10A | I105: Fast trip via shunt coil | J105: 57mm x 13mm | K105: IP41 (Internal) | L105: Fuse dimensions: Length 57mm x Diameter 13mm; Shunted with circuit breaker trip coil fed from CT; Zero capacitor charging time lag; Overcurrent & earth fault protection; Standards: ENA TS 12-6, ENA TS 41-36 | M105: USD | N105: 5 | P105: =IF(ISNUMBER(N105),N105*(1-O105),N105) | Q105: Quoted in Catalogue | R105: In Stock (Immediate Dispatch) | S105: Fuse Clips in Front LV Panel | T105: ENA TS 12-6, ENA TS 41-36, IEC 62271-105 | U105: Page 23
A106: Circuit Breaker Protection (TLF) | B106: Protection Fuses & Links | C106: Aegis Protection | D106: TLF-12.5A | E106: Fuse Link 12.5A | F106: Time Limit Fuse Link 12.5A (57mm x 13mm) for Transformer Fault Protection | G106: 3.3 - 24kV | H106: 12.5A | I106: Fast trip via shunt coil | J106: 57mm x 13mm | K106: IP41 (Internal) | L106: Fuse dimensions: Length 57mm x Diameter 13mm; Shunted with circuit breaker trip coil fed from CT; Zero capacitor charging time lag; Overcurrent & earth fault protection; Standards: ENA TS 12-6, ENA TS 41-36 | M106: USD | N106: 5 | P106: =IF(ISNUMBER(N106),N106*(1-O106),N106) | Q106: Quoted in Catalogue | R106: In Stock (Immediate Dispatch) | S106: Fuse Clips in Front LV Panel | T106: ENA TS 12-6, ENA TS 41-36, IEC 62271-105 | U106: Page 23
A107: Circuit Breaker Protection (TLF) | B107: Protection Fuses & Links | C107: Aegis Protection | D107: TLF-15A | E107: Fuse Link 15A | F107: Time Limit Fuse Link 15A (57mm x 13mm) for Transformer Fault Protection | G107: 3.3 - 24kV | H107: 15A | I107: Fast trip via shunt coil | J107: 57mm x 13mm | K107: IP41 (Internal) | L107: Fuse dimensions: Length 57mm x Diameter 13mm; Shunted with circuit breaker trip coil fed from CT; Zero capacitor charging time lag; Overcurrent & earth fault protection; Standards: ENA TS 12-6, ENA TS 41-36 | M107: USD | N107: 5 | P107: =IF(ISNUMBER(N107),N107*(1-O107),N107) | Q107: Quoted in Catalogue | R107: In Stock (Immediate Dispatch) | S107: Fuse Clips in Front LV Panel | T107: ENA TS 12-6, ENA TS 41-36, IEC 62271-105 | U107: Page 23
A108: Circuit Breaker Protection (TLF) | B108: Protection Fuses & Links | C108: Aegis Protection | D108: HV-FUSE-SET | E108: Fuse Link Up to 200A | F108: High Voltage Fuse-Links Set for F Switch (Transformer Protection up to 1000kVA) | G108: 12 - 24kV | H108: Up to 200A | I108: Fast trip via shunt coil | J108: Standard DIN HV fuse | K108: IP41 (Internal) | L108: Fuse dimensions: Length 57mm x Diameter 13mm; Shunted with circuit breaker trip coil fed from CT; Zero capacitor charging time lag; Overcurrent & earth fault protection; Standards: ENA TS 12-6, ENA TS 41-36 | M108: USD | N108: 50 | P108: =IF(ISNUMBER(N108),N108*(1-O108),N108) | Q108: Quoted in Catalogue | R108: In Stock (Immediate Dispatch) | S108: Fuse Clips in Front LV Panel | T108: ENA TS 12-6, ENA TS 41-36, IEC 62271-105 | U108: Page 23
A109: Protection Relays | B109: Numerical & Self-Powered Relays | C109: Woodward Relay Series | D109: WIP1 | E109: Woodward WIP1 | F109: WIP1 Self & Dual Powered Overcurrent & Earth Fault Protection Relay | G109: Self-powered from CT / Aux 24-230V AC/DC | H109: 1A / 5A CT Secondary | I109: - | J109: Standard DIN Flush Panel Mount | K109: IP54 Front Face | L109: Eliminates reliance on external power supplies; Fault current recording; Non-volatile event memory; Secondary injection testing support; Operating temp: -30°C to +70°C; Standards: IEC 60255 | M109: USD / Upon Request | N109: Upon request | P109: =IF(ISNUMBER(N109),N109*(1-O109),N109) | Q109: Upon request | R109: Available from stock (1-2 weeks) | S109: Fascia Panel Cutout | T109: IEC 60255, IEC 61000 | U109: Page 25
A110: Protection Relays | B110: Numerical & Self-Powered Relays | C110: Woodward Relay Series | D110: WIC1 | E110: Woodward WIC1 | F110: WIC1 Self-Powered Overcurrent and Earth Fault Protection Relay | G110: Self-powered from CT / Aux 24-230V AC/DC | H110: 1A / 5A CT Secondary | I110: - | J110: Standard DIN Flush Panel Mount | K110: IP54 Front Face | L110: Eliminates reliance on external power supplies; Fault current recording; Non-volatile event memory; Secondary injection testing support; Operating temp: -30°C to +70°C; Standards: IEC 60255 | M110: USD / Upon Request | N110: Upon request | P110: =IF(ISNUMBER(N110),N110*(1-O110),N110) | Q110: Upon request | R110: Available from stock (1-2 weeks) | S110: Fascia Panel Cutout | T110: IEC 60255, IEC 61000 | U110: Page 46
A111: Protection Relays | B111: Numerical & Self-Powered Relays | C111: Ashida Relay Series | D111: ADR241S | E111: Ashida ADR241S | F111: ADR241S Numerical Feeder Protection Relay (Dual Powered) | G111: Self-powered from CT / Aux 24-230V AC/DC | H111: 1A / 5A CT Secondary | I111: - | J111: Standard DIN Flush Panel Mount | K111: IP54 Front Face | L111: Eliminates reliance on external power supplies; Fault current recording; Non-volatile event memory; Secondary injection testing support; Operating temp: -30°C to +70°C; Standards: IEC 60255 | M111: USD / Upon Request | N111: Upon request | P111: =IF(ISNUMBER(N111),N111*(1-O111),N111) | Q111: Upon request | R111: Available from stock (1-2 weeks) | S111: Fascia Panel Cutout | T111: IEC 60255, IEC 61000 | U111: Page 25
A112: Protection Relays | B112: Numerical & Self-Powered Relays | C112: Kries Relay Series | D112: IKI-35 | E112: Kries IKI-35 | F112: IKI-35 Feeder Protection Relay with Integrated CT Inputs | G112: Self-powered from CT / Aux 24-230V AC/DC | H112: 1A / 5A CT Secondary | I112: - | J112: Standard DIN Flush Panel Mount | K112: IP54 Front Face | L112: Eliminates reliance on external power supplies; Fault current recording; Non-volatile event memory; Secondary injection testing support; Operating temp: -30°C to +70°C; Standards: IEC 60255 | M112: USD / Upon Request | N112: Upon request | P112: =IF(ISNUMBER(N112),N112*(1-O112),N112) | Q112: Upon request | R112: Available from stock (1-2 weeks) | S112: Fascia Panel Cutout | T112: IEC 60255, IEC 61000 | U112: Page 25
A113: Protection Relays | B113: Numerical & Self-Powered Relays | C113: Fanox Relay Series | D113: SIA-C | E113: Fanox SIA-C | F113: SIA-C Dual Powered Protection Relay with Peak Demand & Modbus | G113: Self-powered from CT / Aux 24-230V AC/DC | H113: 1A / 5A CT Secondary | I113: - | J113: Standard DIN Flush Panel Mount | K113: IP54 Front Face | L113: Eliminates reliance on external power supplies; Fault current recording; Non-volatile event memory; Secondary injection testing support; Operating temp: -30°C to +70°C; Standards: IEC 60255 | M113: USD / Upon Request | N113: Upon request | P113: =IF(ISNUMBER(N113),N113*(1-O113),N113) | Q113: Upon request | R113: Available from stock (1-2 weeks) | S113: Fascia Panel Cutout | T113: IEC 60255, IEC 61000 | U113: Page 25
A114: Protection Relays | B114: Numerical & Self-Powered Relays | C114: Fanox Relay Series | D114: SIA-B | E114: Fanox SIA-B | F114: SIA-B Overcurrent, Earth Fault & Thermal Overload Protection Relay | G114: Self-powered from CT / Aux 24-230V AC/DC | H114: 1A / 5A CT Secondary | I114: - | J114: Standard DIN Flush Panel Mount | K114: IP54 Front Face | L114: Eliminates reliance on external power supplies; Fault current recording; Non-volatile event memory; Secondary injection testing support; Operating temp: -30°C to +70°C; Standards: IEC 60255 | M114: USD / Upon Request | N114: Upon request | P114: =IF(ISNUMBER(N114),N114*(1-O114),N114) | Q114: Upon request | R114: Available from stock (1-2 weeks) | S114: Fascia Panel Cutout | T114: IEC 60255, IEC 61000 | U114: Page 25
A115: Protection Relays | B115: Numerical & Self-Powered Relays | C115: C&S Electric Relay Series | D115: CSPR-V2 | E115: C&S Electric CSPR-V2 | F115: CSPR-V2 Self-Powered Microcontroller Protection Relay | G115: Self-powered from CT / Aux 24-230V AC/DC | H115: 1A / 5A CT Secondary | I115: - | J115: Standard DIN Flush Panel Mount | K115: IP54 Front Face | L115: Eliminates reliance on external power supplies; Fault current recording; Non-volatile event memory; Secondary injection testing support; Operating temp: -30°C to +70°C; Standards: IEC 60255 | M115: USD / Upon Request | N115: Upon request | P115: =IF(ISNUMBER(N115),N115*(1-O115),N115) | Q115: Upon request | R115: Available from stock (1-2 weeks) | S115: Fascia Panel Cutout | T115: IEC 60255, IEC 61000 | U115: Page 46
A116: Earth Fault Indicators (EFI) | B116: Fault Passage Indicators | C116: Horstmann EFI Series | D116: SIGMA F+E 3 | E116: Horstmann SIGMA F+E 3 | F116: Horstmann SIGMA F+E 3 Non-Directional Short-Circuit & Earth Fault Indicator | G116: 1 - 38kV Medium Voltage Networks | H116: 50A Trip Current | I116: - | J116: 96 x 48 mm DIN cutout | K116: IP40 | L116: Trip current: 50A; Minimum fault duration: 2.5 cycles; Operating temp: -30°C to +70°C (-40°C to +80°C for SupaRule); Automatic timer reset (4 or 8h / 10s after mains restore); Manual reset push button | M116: USD / Upon Request | N116: Upon request | P116: =IF(ISNUMBER(N116),N116*(1-O116),N116) | Q116: Upon request | R116: In Stock (Immediate Dispatch) | S116: Fascia DIN Cutout / Surface Mount | T116: IEC 61010, IEEE 495 | U116: Page 26
A117: Earth Fault Indicators (EFI) | B117: Fault Passage Indicators | C117: Horstmann EFI Series | D117: SIGMA D/D+ | E117: Horstmann SIGMA D/D+ | F117: Horstmann SIGMA D/D+ Directional Short-Circuit & Earth Fault Indicator | G117: 1 - 38kV Medium Voltage Networks | H117: 50A Trip Current | I117: - | J117: 96 x 48 mm DIN cutout | K117: IP40 | L117: Trip current: 50A; Minimum fault duration: 2.5 cycles; Operating temp: -30°C to +70°C (-40°C to +80°C for SupaRule); Automatic timer reset (4 or 8h / 10s after mains restore); Manual reset push button | M117: USD / Upon Request | N117: Upon request | P117: =IF(ISNUMBER(N117),N117*(1-O117),N117) | Q117: Upon request | R117: In Stock (Immediate Dispatch) | S117: Fascia DIN Cutout / Surface Mount | T117: IEC 61010, IEEE 495 | U117: Page 26
A118: Earth Fault Indicators (EFI) | B118: Fault Passage Indicators | C118: Horstmann EFI Series | D118: ComPass A | E118: Horstmann ComPass A | F118: Horstmann ComPass A Non-Directional EFI with RS485 Modbus RTU | G118: 1 - 38kV Medium Voltage Networks | H118: 50A Trip Current | I118: - | J118: 96 x 48 mm DIN cutout | K118: IP50 | L118: Trip current: 50A; Minimum fault duration: 2.5 cycles; Operating temp: -30°C to +70°C (-40°C to +80°C for SupaRule); Automatic timer reset (4 or 8h / 10s after mains restore); Manual reset push button | M118: USD / Upon Request | N118: Upon request | P118: =IF(ISNUMBER(N118),N118*(1-O118),N118) | Q118: Upon request | R118: In Stock (Immediate Dispatch) | S118: Fascia DIN Cutout / Surface Mount | T118: IEC 61010, IEEE 495 | U118: Page 26
A119: Earth Fault Indicators (EFI) | B119: Fault Passage Indicators | C119: Horstmann EFI Series | D119: ComPass B | E119: Horstmann ComPass B | F119: Horstmann ComPass B Directional EFI with RS485 Modbus RTU | G119: 1 - 38kV Medium Voltage Networks | H119: 50A Trip Current | I119: - | J119: 96 x 48 mm DIN cutout | K119: IP50 | L119: Trip current: 50A; Minimum fault duration: 2.5 cycles; Operating temp: -30°C to +70°C (-40°C to +80°C for SupaRule); Automatic timer reset (4 or 8h / 10s after mains restore); Manual reset push button | M119: USD / Upon Request | N119: Upon request | P119: =IF(ISNUMBER(N119),N119*(1-O119),N119) | Q119: Upon request | R119: In Stock (Immediate Dispatch) | S119: Fascia DIN Cutout / Surface Mount | T119: IEC 61010, IEEE 495 | U119: Page 26
A120: Earth Fault Indicators (EFI) | B120: Fault Passage Indicators | C120: Horstmann EFI Series | D120: EARTH Zero (PI) | E120: Horstmann EARTH Zero (PI) | F120: Horstmann EARTH Zero Earth Fault Indicator (Plug-in Housing) | G120: 1 - 38kV Medium Voltage Networks | H120: 50A Trip Current | I120: - | J120: 96 x 48 mm DIN cutout | K120: IP40 | L120: Trip current: 50A; Minimum fault duration: 2.5 cycles; Operating temp: -30°C to +70°C (-40°C to +80°C for SupaRule); Automatic timer reset (4 or 8h / 10s after mains restore); Manual reset push button | M120: USD / Upon Request | N120: Upon request | P120: =IF(ISNUMBER(N120),N120*(1-O120),N120) | Q120: Upon request | R120: In Stock (Immediate Dispatch) | S120: Fascia DIN Cutout / Surface Mount | T120: IEC 61010, IEEE 495 | U120: Page 27
... A253: Enclosure & Venting Accessories | B253: Enclosures & Arc Protection Kits | C253: Aegis Plus Enclosure | D253: CLAMP-PLASTIC-3C | E253: Enclosure CLAMP-PLASTIC-3C | F253: Plastic Insulated Cable Clamps Kit for Three Core Polymeric Cables | G253: - | H253: - | I253: - | J253: 450/600/750mm Height Variants | K253: IP41 / IP54 | L253: Plastic Insulated Cable Clamps Kit for Three Core Polymeric Cables. Electro-statically applied oven cured paint; Zinc coated steel housing; Suitable for harsh environmental conditions and pollution resistance | M253: USD / Upon Request | N253: Upon request | P253: =IF(ISNUMBER(N253),N253*(1-O253),N253) | Q253: Upon request | R253: Available from stock / order (2-4 weeks) | S253: Switchgear Front Compartment | T253: IEC 62271-200 Internal Arc Classified (IAC) | U253: Page 45

Sheet Notes
A1: How to use
