Workbook

Sheet Schneider Automation Price List
A1: Schneider Electric Industrial Automation Products Price List - effective 01 April 2026
A2: Prices in INR (Rs.) as printed in the Schneider Electric list (L.P./M.R.P.). Enter Discount as % (e.g. 35%); Net Price = Price x (1 - Discount).
A4: Sr. No. | B4: Manufacturer | C4: Category | D4: Description | E4: Key word | F4: Rating 1 | G4: Rating 2 | H4: Rating 3 | I4: Rating 4 | J4: Rating 5 | K4: Accessories | L4: Stocked or Not stocked | M4: Part code | N4: Discount | O4: Price | P4: Net Price | Q4: Product Range / Series | R4: Other Ratings / Specs | S4: Suitable for (Accessories) | T4: Std Pack | U4: Remarks | V4: Price List Page
A5: 1 | B5: Schneider Electric | C5: Power Supplies (Phaseo) | D5: ABL2_K Power Supply, DC24V output, 35W | E5: Phaseo Easy ABL2 35W | F5: Input: 100-240V AC 1-Ph | G5: Output: 24V | H5: Current: 1.5A | I5: Power: 35W | J5: Mounting: Panel Mount | K5: Power Supply | L5: Stocked | M5: ABL2REM24015K | O5: 3061 | P5: =IF(ISNUMBER(O5),O5*(1-N5),O5) | Q5: Phaseo ABL2 | R5: Output stability +/-1%; MTBF >600k hours; Diagnostic LED; Input 100-240V AC | S5: - | T5: 1 | U5: Compact panel mount | V5: 5
A6: 2 | B6: Schneider Electric | C6: Power Supplies (Phaseo) | D6: ABL2_K Power Supply, DC24V output, 50W | E6: Phaseo Easy ABL2 50W | F6: Input: 100-240V AC 1-Ph | G6: Output: 24V | H6: Current: 2A | I6: Power: 50W | J6: Mounting: Panel Mount | K6: Power Supply | L6: Stocked | M6: ABL2REM24020K | O6: 3393 | P6: =IF(ISNUMBER(O6),O6*(1-N6),O6) | Q6: Phaseo ABL2 | R6: Output stability +/-1%; MTBF >600k hours; Diagnostic LED; Input 100-240V AC | S6: - | T6: 1 | U6: Compact panel mount | V6: 5
A7: 3 | B7: Schneider Electric | C7: Power Supplies (Phaseo) | D7: ABL2_K Power Supply, DC24V output, 100W | E7: Phaseo Easy ABL2 100W | F7: Input: 100-240V AC 1-Ph | G7: Output: 24V | H7: Current: 4.5A | I7: Power: 100W | J7: Mounting: Panel Mount | K7: Power Supply | L7: Stocked | M7: ABL2REM24045K | O7: 5024 | P7: =IF(ISNUMBER(O7),O7*(1-N7),O7) | Q7: Phaseo ABL2 | R7: Output stability +/-1%; MTBF >600k hours; Diagnostic LED; Input 100-240V AC | S7: - | T7: 1 | U7: Compact panel mount | V7: 5
A8: 4 | B8: Schneider Electric | C8: Power Supplies (Phaseo) | D8: ABL2_K Power Supply, DC24V output, 150W | E8: Phaseo Easy ABL2 150W | F8: Input: 100-240V AC 1-Ph | G8: Output: 24V | H8: Current: 6.5A | I8: Power: 150W | J8: Mounting: Panel Mount | K8: Power Supply | L8: Stocked | M8: ABL2REM24065K | O8: 6061 | P8: =IF(ISNUMBER(O8),O8*(1-N8),O8) | Q8: Phaseo ABL2 | R8: Output stability +/-1%; MTBF >600k hours; Diagnostic LED; Input 100-240V AC | S8: - | T8: 1 | U8: Compact panel mount | V8: 5
A9: 5 | B9: Schneider Electric | C9: Power Supplies (Phaseo) | D9: ABL2_K Power Supply, DC24V output, 200W | E9: Phaseo Easy ABL2 200W | F9: Input: 100-240V AC 1-Ph | G9: Output: 24V | H9: Current: 8.5A | I9: Power: 200W | J9: Mounting: Panel Mount | K9: Power Supply | L9: Stocked | M9: ABL2REM24085K | O9: 8038 | P9: =IF(ISNUMBER(O9),O9*(1-N9),O9) | Q9: Phaseo ABL2 | R9: Output stability +/-1%; MTBF >600k hours; Diagnostic LED; Input 100-240V AC | S9: - | T9: 1 | U9: Compact panel mount | V9: 5
A10: 6 | B10: Schneider Electric | C10: Power Supplies (Phaseo) | D10: ABL2_K Power Supply, DC24V output, 250W | E10: Phaseo Easy ABL2 250W | F10: Input: 100-240V AC 1-Ph | G10: Output: 24V | H10: Current: 10A | I10: Power: 250W | J10: Mounting: Panel Mount | K10: Power Supply | L10: Stocked | M10: ABL2REM24100K | O10: 9194 | P10: =IF(ISNUMBER(O10),O10*(1-N10),O10) | Q10: Phaseo ABL2 | R10: Output stability +/-1%; MTBF >600k hours; Diagnostic LED; Input 100-240V AC | S10: - | T10: 1 | U10: Compact panel mount | V10: 5
A11: 7 | B11: Schneider Electric | C11: Power Supplies (Phaseo) | D11: ABL2_K Power Supply, DC24V output, 350W | E11: Phaseo Easy ABL2 350W | F11: Input: 100-240V AC 1-Ph | G11: Output: 24V | H11: Current: 15A | I11: Power: 350W | J11: Mounting: Panel Mount | K11: Power Supply | L11: Stocked | M11: ABL2REM24150K | O11: 14992 | P11: =IF(ISNUMBER(O11),O11*(1-N11),O11) | Q11: Phaseo ABL2 | R11: Output stability +/-1%; MTBF >600k hours; Diagnostic LED; Input 100-240V AC | S11: - | T11: 1 | U11: Compact panel mount | V11: 5
A12: 8 | B12: Schneider Electric | C12: Power Supplies (Phaseo) | D12: Univ. Power Supply 1P 24V 3A, 72W | E12: Phaseo ABL8 72W | F12: Input: 100-120V / 200-500V AC | G12: Output: 24V | H12: Current: 3A | I12: Power: 72W | J12: Mounting: DIN Rail | K12: Power Supply | L12: Stocked | M12: ABL8RPS24030 | O12: 21487 | P12: =IF(ISNUMBER(O12),O12*(1-N12),O12) | Q12: Phaseo ABL8 | R12: 1 or 2 phase input; Auto/manual reset; 2 diagnosis LEDs; Diagnosis relay output | S12: - | T12: 1 | U12: High reliability industrial | V12: 5
A13: 9 | B13: Schneider Electric | C13: Power Supplies (Phaseo) | D13: Univ. Power Supply 1P 24V 5A, 120W | E13: Phaseo ABL8 120W | F13: Input: 100-120V / 200-500V AC | G13: Output: 24V | H13: Current: 5A | I13: Power: 120W | J13: Mounting: DIN Rail | K13: Power Supply | L13: Stocked | M13: ABL8RPS24050 | O13: 27778 | P13: =IF(ISNUMBER(O13),O13*(1-N13),O13) | Q13: Phaseo ABL8 | R13: 1 or 2 phase input; Auto/manual reset; 2 diagnosis LEDs; Diagnosis relay output | S13: - | T13: 1 | U13: High reliability industrial | V13: 5
A14: 10 | B14: Schneider Electric | C14: Power Supplies (Phaseo) | D14: Univ. Power Supply 1P 24V 10A, 240W | E14: Phaseo ABL8 240W | F14: Input: 100-120V / 200-500V AC | G14: Output: 24V | H14: Current: 10A | I14: Power: 240W | J14: Mounting: DIN Rail | K14: Power Supply | L14: Stocked | M14: ABL8RPS24100 | O14: 31734 | P14: =IF(ISNUMBER(O14),O14*(1-N14),O14) | Q14: Phaseo ABL8 | R14: 1 or 2 phase input; Auto/manual reset; 2 diagnosis LEDs; Diagnosis relay output | S14: - | T14: 1 | U14: High reliability industrial | V14: 5
A15: 11 | B15: Schneider Electric | C15: Power Supplies (Phaseo) | D15: Univ. Power Supply 1P 24V 20A, 480W | E15: Phaseo ABL8 480W | F15: Input: 100-120V / 200-500V AC | G15: Output: 24V | H15: Current: 20A | I15: Power: 480W | J15: Mounting: DIN Rail | K15: Power Supply | L15: Stocked | M15: ABL8RPM24200 | O15: 47764 | P15: =IF(ISNUMBER(O15),O15*(1-N15),O15) | Q15: Phaseo ABL8 | R15: 1 or 2 phase input; Auto/manual reset; 2 diagnosis LEDs; Diagnosis relay output | S15: - | T15: 1 | U15: High reliability industrial | V15: 5
A16: 12 | B16: Schneider Electric | C16: Power Supplies (Phaseo) | D16: POWER SUPPLY 12V 6.2A 1PH OPTIMIZED | E16: Phaseo ABLS 75W | F16: Input: 100-240V AC 1-Ph | G16: Output: 12V | H16: Current: 6.2A | I16: Power: 75W | J16: Operating Temp: Up to 70 deg C | K16: Power Supply | L16: Stocked | M16: ABLS1A12062 | O16: 10652 | P16: =IF(ISNUMBER(O16),O16*(1-N16),O16) | Q16: Phaseo ABLS | R16: Conformal coating; 6 output terminals; High output stability; Operating up to +70 deg C | S16: - | T16: 1 | U16: Optimised compact design | V16: 6
... A75: 71 | B75: Schneider Electric | C75: Smart Relays (Harmony Zelio) | D75: USB PC connecting cable - 3 m | E75: Zelio Acc SR2USB01 | F75: Type: Cable | G75: Spec: Length: 3m | H75: Series: SR3 / SR2 | I75: - | J75: - | K75: Accessory / Extension | L75: Stocked | M75: SR2USB01 | O75: 20194 | P75: =IF(ISNUMBER(O75),O75*(1-N75),O75) | Q75: Harmony Zelio | R75: USB PC connecting cable - 3 m | S75: Zelio Logic Modular Relays (SR3B) | T75: 1 | U75: Plugs onto side of SR3B module | V75: 8
A76: 72 | B76: Schneider Electric | C76: Variable Speed Drives (Altivar) | D76: Altivar 12 Drive 0.18kW 0.25HP 1-Phase 200-240V | E76: Altivar ATV12H018M2 | F76: Supply: 1-Ph 200-240V | G76: Power: 0.18kW / 0.25HP | H76: Current: 1.4A | I76: Control: V/f & Sensorless Vector | J76: Modbus Embedded | K76: AC Variable Speed Drive | L76: Stocked | M76: ATV12H018M2 | O76: On Request | P76: =IF(ISNUMBER(O76),O76*(1-N76),O76) | Q76: Altivar ATV12 / ATV310 | R76: Integrated Modbus; 55 deg C without derating; Optimized panel space; Built-in brake chopper | S76: - | T76: 1 | U76: Quote upon application rating | V76: 11
A77: 73 | B77: Schneider Electric | C77: Variable Speed Drives (Altivar) | D77: Altivar 12 Drive 0.37kW 0.55HP 1-Phase 200-240V | E77: Altivar ATV12H037M2 | F77: Supply: 1-Ph 200-240V | G77: Power: 0.37kW / 0.55HP | H77: Current: 2.4A | I77: Control: V/f & Sensorless Vector | J77: Modbus Embedded | K77: AC Variable Speed Drive | L77: Stocked | M77: ATV12H037M2 | O77: On Request | P77: =IF(ISNUMBER(O77),O77*(1-N77),O77) | Q77: Altivar ATV12 / ATV310 | R77: Integrated Modbus; 55 deg C without derating; Optimized panel space; Built-in brake chopper | S77: - | T77: 1 | U77: Quote upon application rating | V77: 11
A78: 74 | B78: Schneider Electric | C78: Variable Speed Drives (Altivar) | D78: Altivar 12 Drive 0.55kW 0.75HP 1-Phase 200-240V | E78: Altivar ATV12H055M2 | F78: Supply: 1-Ph 200-240V | G78: Power: 0.55kW / 0.75HP | H78: Current: 3.5A | I78: Control: V/f & Sensorless Vector | J78: Modbus Embedded | K78: AC Variable Speed Drive | L78: Stocked | M78: ATV12H055M2 | O78: On Request | P78: =IF(ISNUMBER(O78),O78*(1-N78),O78) | Q78: Altivar ATV12 / ATV310 | R78: Integrated Modbus; 55 deg C without derating; Optimized panel space; Built-in brake chopper | S78: - | T78: 1 | U78: Quote upon application rating | V78: 11
A79: 75 | B79: Schneider Electric | C79: Variable Speed Drives (Altivar) | D79: Altivar 12 Drive 0.75kW 1HP 1-Phase 200-240V | E79: Altivar ATV12H075M2 | F79: Supply: 1-Ph 200-240V | G79: Power: 0.75kW / 1.0HP | H79: Current: 4.2A | I79: Control: V/f & Sensorless Vector | J79: Modbus Embedded | K79: AC Variable Speed Drive | L79: Stocked | M79: ATV12H075M2 | O79: On Request | P79: =IF(ISNUMBER(O79),O79*(1-N79),O79) | Q79: Altivar ATV12 / ATV310 | R79: Integrated Modbus; 55 deg C without derating; Optimized panel space; Built-in brake chopper | S79: - | T79: 1 | U79: Quote upon application rating | V79: 11
A80: 76 | B80: Schneider Electric | C80: Variable Speed Drives (Altivar) | D80: Altivar 12 Drive 1.5kW 2HP 1-Phase 200-240V | E80: Altivar ATV12HU15M2 | F80: Supply: 1-Ph 200-240V | G80: Power: 1.5kW / 2.0HP | H80: Current: 7.5A | I80: Control: V/f & Sensorless Vector | J80: Modbus Embedded | K80: AC Variable Speed Drive | L80: Stocked | M80: ATV12HU15M2 | O80: On Request | P80: =IF(ISNUMBER(O80),O80*(1-N80),O80) | Q80: Altivar ATV12 / ATV310 | R80: Integrated Modbus; 55 deg C without derating; Optimized panel space; Built-in brake chopper | S80: - | T80: 1 | U80: Quote upon application rating | V80: 11
A81: 77 | B81: Schneider Electric | C81: Variable Speed Drives (Altivar) | D81: Altivar 12 Drive 2.2kW 3HP 1-Phase 200-240V | E81: Altivar ATV12HU22M2 | F81: Supply: 1-Ph 200-240V | G81: Power: 2.2kW / 3.0HP | H81: Current: 10A | I81: Control: V/f & Sensorless Vector | J81: Modbus Embedded | K81: AC Variable Speed Drive | L81: Stocked | M81: ATV12HU22M2 | O81: On Request | P81: =IF(ISNUMBER(O81),O81*(1-N81),O81) | Q81: Altivar ATV12 / ATV310 | R81: Integrated Modbus; 55 deg C without derating; Optimized panel space; Built-in brake chopper | S81: - | T81: 1 | U81: Quote upon application rating | V81: 11
A82: 78 | B82: Schneider Electric | C82: Variable Speed Drives (Altivar) | D82: Altivar 12 Drive 0.37kW 0.55HP 3-Phase 200-240V | E82: Altivar ATV12H037M3 | F82: Supply: 3-Ph 200-240V | G82: Power: 0.37kW / 0.55HP | H82: Current: 2.4A | I82: Control: V/f & Sensorless Vector | J82: Modbus Embedded | K82: AC Variable Speed Drive | L82: Stocked | M82: ATV12H037M3 | O82: On Request | P82: =IF(ISNUMBER(O82),O82*(1-N82),O82) | Q82: Altivar ATV12 / ATV310 | R82: Integrated Modbus; 55 deg C without derating; Optimized panel space; Built-in brake chopper | S82: - | T82: 1 | U82: Quote upon application rating | V82: 11
A83: 79 | B83: Schneider Electric | C83: Variable Speed Drives (Altivar) | D83: Altivar 12 Drive 0.75kW 1HP 3-Phase 200-240V | E83: Altivar ATV12H075M3 | F83: Supply: 3-Ph 200-240V | G83: Power: 0.75kW / 1.0HP | H83: Current: 4.2A | I83: Control: V/f & Sensorless Vector | J83: Modbus Embedded | K83: AC Variable Speed Drive | L83: Stocked | M83: ATV12H075M3 | O83: On Request | P83: =IF(ISNUMBER(O83),O83*(1-N83),O83) | Q83: Altivar ATV12 / ATV310 | R83: Integrated Modbus; 55 deg C without derating; Optimized panel space; Built-in brake chopper | S83: - | T83: 1 | U83: Quote upon application rating | V83: 11
A84: 80 | B84: Schneider Electric | C84: Variable Speed Drives (Altivar) | D84: Altivar 12 Drive 1.5kW 2HP 3-Phase 200-240V | E84: Altivar ATV12HU15M3 | F84: Supply: 3-Ph 200-240V | G84: Power: 1.5kW / 2.0HP | H84: Current: 7.5A | I84: Control: V/f & Sensorless Vector | J84: Modbus Embedded | K84: AC Variable Speed Drive | L84: Stocked | M84: ATV12HU15M3 | O84: On Request | P84: =IF(ISNUMBER(O84),O84*(1-N84),O84) | Q84: Altivar ATV12 / ATV310 | R84: Integrated Modbus; 55 deg C without derating; Optimized panel space; Built-in brake chopper | S84: - | T84: 1 | U84: Quote upon application rating | V84: 11
A85: 81 | B85: Schneider Electric | C85: Variable Speed Drives (Altivar) | D85: Altivar 12 Drive 2.2kW 3HP 3-Phase 200-240V | E85: Altivar ATV12HU22M3 | F85: Supply: 3-Ph 200-240V | G85: Power: 2.2kW / 3.0HP | H85: Current: 10A | I85: Control: V/f & Sensorless Vector | J85: Modbus Embedded | K85: AC Variable Speed Drive | L85: Stocked | M85: ATV12HU22M3 | O85: On Request | P85: =IF(ISNUMBER(O85),O85*(1-N85),O85) | Q85: Altivar ATV12 / ATV310 | R85: Integrated Modbus; 55 deg C without derating; Optimized panel space; Built-in brake chopper | S85: - | T85: 1 | U85: Quote upon application rating | V85: 11
A86: 82 | B86: Schneider Electric | C86: Variable Speed Drives (Altivar) | D86: Altivar 12 Drive 3kW 3-Phase 200-240V | E86: Altivar ATV12HU30M3 | F86: Supply: 3-Ph 200-240V | G86: Power: 3.0kW | H86: Current: 12.2A | I86: Control: V/f & Sensorless Vector | J86: Modbus Embedded | K86: AC Variable Speed Drive | L86: Stocked | M86: ATV12HU30M3 | O86: On Request | P86: =IF(ISNUMBER(O86),O86*(1-N86),O86) | Q86: Altivar ATV12 / ATV310 | R86: Integrated Modbus; 55 deg C without derating; Optimized panel space; Built-in brake chopper | S86: - | T86: 1 | U86: Quote upon application rating | V86: 11
A87: 83 | B87: Schneider Electric | C87: Variable Speed Drives (Altivar) | D87: Altivar 12 Drive 4kW 5HP 3-Phase 200-240V | E87: Altivar ATV12HU40M3 | F87: Supply: 3-Ph 200-240V | G87: Power: 4.0kW / 5.0HP | H87: Current: 16.7A | I87: Control: V/f & Sensorless Vector | J87: Modbus Embedded | K87: AC Variable Speed Drive | L87: Stocked | M87: ATV12HU40M3 | O87: On Request | P87: =IF(ISNUMBER(O87),O87*(1-N87),O87) | Q87: Altivar ATV12 / ATV310 | R87: Integrated Modbus; 55 deg C without derating; Optimized panel space; Built-in brake chopper | S87: - | T87: 1 | U87: Quote upon application rating | V87: 11
... A204: 200 | B204: Schneider Electric | C204: Soft Starters (Altistart/Altivar) | D204: ATS490 Soft Starter 1200A 630-900kW | E204: ATS490 ATS490M12Y | F204: Supply: 208-690V 3-Ph | G204: Current: 1200A | H204: Power: 630-900kW | I204: Integrated Bypass | J204: Torque Control System | K204: Soft Starter | L204: Stocked | M204: ATS490M12Y | O204: On Request | P204: =IF(ISNUMBER(O204),O204*(1-N204),O204) | Q204: Altivar ATS490 | R204: Torque control original; Integrated bypass; Cybersecure IEC 62443; Modbus TCP / Ethernet IP | S204: - | T204: 1 | U204: Next-gen industrial soft starter | V204: 25
A205: 201 | B205: Schneider Electric | C205: Plug-in Relays (Harmony) | D205: 1CO 6 Pin Relay Standard cover lockable test button w/o LED 24V DC | E205: RXG RXG11BD | F205: Contacts: 1 CO - 10 A | G205: Control Voltage: 24V DC | H205: Pins: 6-pin / 8-pin | I205: Mounting: Socket Mount | J205: - | K205: Interface Relay | L205: Stocked | M205: RXG11BD | O205: 690 | P205: =IF(ISNUMBER(O205),O205*(1-N205),O205) | Q205: Harmony RXG | R205: Fast-on pin terminal; Optional lockable test button; 16mm socket width | S205: RGZE sockets | T205: 10 | U205: Pluggable interface relay | V205: 27
A206: 202 | B206: Schneider Electric | C206: Plug-in Relays (Harmony) | D206: 1CO 6 Pin Relay Standard cover lockable test button w/o LED 120V AC | E206: RXG RXG11F7 | F206: Contacts: 1 CO - 10 A | G206: Control Voltage: 120V AC | H206: Pins: 6-pin / 8-pin | I206: Mounting: Socket Mount | J206: - | K206: Interface Relay | L206: Stocked | M206: RXG11F7 | O206: 911 | P206: =IF(ISNUMBER(O206),O206*(1-N206),O206) | Q206: Harmony RXG | R206: Fast-on pin terminal; Optional lockable test button; 16mm socket width | S206: RGZE sockets | T206: 10 | U206: Pluggable interface relay | V206: 27
A207: 203 | B207: Schneider Electric | C207: Plug-in Relays (Harmony) | D207: 1CO 6 Pin Relay Standard cover lockable test button w/o LED 230V AC | E207: RXG RXG11P7 | F207: Contacts: 1 CO - 10 A | G207: Control Voltage: 230V AC | H207: Pins: 6-pin / 8-pin | I207: Mounting: Socket Mount | J207: - | K207: Interface Relay | L207: Stocked | M207: RXG11P7 | O207: 859 | P207: =IF(ISNUMBER(O207),O207*(1-N207),O207) | Q207: Harmony RXG | R207: Fast-on pin terminal; Optional lockable test button; 16mm socket width | S207: RGZE sockets | T207: 10 | U207: Pluggable interface relay | V207: 27
A208: 204 | B208: Schneider Electric | C208: Plug-in Relays (Harmony) | D208: 1CO 6 Pin Relay Standard cover lockable test button with LED 24V DC | E208: RXG RXG12BD | F208: Contacts: 1 CO - 10 A | G208: Control Voltage: 24V DC | H208: Pins: 6-pin / 8-pin | I208: Mounting: Socket Mount | J208: - | K208: Interface Relay | L208: Stocked | M208: RXG12BD | O208: 779 | P208: =IF(ISNUMBER(O208),O208*(1-N208),O208) | Q208: Harmony RXG | R208: Fast-on pin terminal; Optional lockable test button; 16mm socket width | S208: RGZE sockets | T208: 10 | U208: Pluggable interface relay | V208: 27
A209: 205 | B209: Schneider Electric | C209: Plug-in Relays (Harmony) | D209: 1CO 6 Pin Relay Standard cover lockable test button with LED 120V AC | E209: RXG RXG12F7 | F209: Contacts: 1 CO - 10 A | G209: Control Voltage: 120V AC | H209: Pins: 6-pin / 8-pin | I209: Mounting: Socket Mount | J209: - | K209: Interface Relay | L209: Stocked | M209: RXG12F7 | O209: 934 | P209: =IF(ISNUMBER(O209),O209*(1-N209),O209) | Q209: Harmony RXG | R209: Fast-on pin terminal; Optional lockable test button; 16mm socket width | S209: RGZE sockets | T209: 10 | U209: Pluggable interface relay | V209: 27
A210: 206 | B210: Schneider Electric | C210: Plug-in Relays (Harmony) | D210: 1CO 6 Pin Relay Standard cover lockable test button with LED 230V AC | E210: RXG RXG12P7 | F210: Contacts: 1 CO - 10 A | G210: Control Voltage: 230V AC | H210: Pins: 6-pin / 8-pin | I210: Mounting: Socket Mount | J210: - | K210: Interface Relay | L210: Stocked | M210: RXG12P7 | O210: 934 | P210: =IF(ISNUMBER(O210),O210*(1-N210),O210) | Q210: Harmony RXG | R210: Fast-on pin terminal; Optional lockable test button; 16mm socket width | S210: RGZE sockets | T210: 10 | U210: Pluggable interface relay | V210: 27
A211: 207 | B211: Schneider Electric | C211: Plug-in Relays (Harmony) | D211: 2CO 8 Pin Relay Standard cover lockable test button w/o LED 24V DC | E211: RXG RXG21BD | F211: Contacts: 2 CO - 5 A | G211: Control Voltage: 24V DC | H211: Pins: 6-pin / 8-pin | I211: Mounting: Socket Mount | J211: - | K211: Interface Relay | L211: Stocked | M211: RXG21BD | O211: 778 | P211: =IF(ISNUMBER(O211),O211*(1-N211),O211) | Q211: Harmony RXG | R211: Fast-on pin terminal; Optional lockable test button; 16mm socket width | S211: RGZE sockets | T211: 10 | U211: Pluggable interface relay | V211: 27
A212: 208 | B212: Schneider Electric | C212: Plug-in Relays (Harmony) | D212: 2CO 8 Pin Relay Standard cover lockable test button w/o LED 120V AC | E212: RXG RXG21F7 | F212: Contacts: 2 CO - 5 A | G212: Control Voltage: 120V AC | H212: Pins: 6-pin / 8-pin | I212: Mounting: Socket Mount | J212: - | K212: Interface Relay | L212: Stocked | M212: RXG21F7 | O212: 944 | P212: =IF(ISNUMBER(O212),O212*(1-N212),O212) | Q212: Harmony RXG | R212: Fast-on pin terminal; Optional lockable test button; 16mm socket width | S212: RGZE sockets | T212: 10 | U212: Pluggable interface relay | V212: 27
A213: 209 | B213: Schneider Electric | C213: Plug-in Relays (Harmony) | D213: 2CO 8 Pin Relay Standard cover lockable test button w/o LED 230V AC | E213: RXG RXG21P7 | F213: Contacts: 2 CO - 5 A | G213: Control Voltage: 230V AC | H213: Pins: 6-pin / 8-pin | I213: Mounting: Socket Mount | J213: - | K213: Interface Relay | L213: Stocked | M213: RXG21P7 | O213: 926 | P213: =IF(ISNUMBER(O213),O213*(1-N213),O213) | Q213: Harmony RXG | R213: Fast-on pin terminal; Optional lockable test button; 16mm socket width | S213: RGZE sockets | T213: 10 | U213: Pluggable interface relay | V213: 27
A214: 210 | B214: Schneider Electric | C214: Plug-in Relays (Harmony) | D214: 2CO 8 Pin Relay Standard cover lockable test button with LED 24V DC | E214: RXG RXG22BD | F214: Contacts: 2 CO - 5 A | G214: Control Voltage: 24V DC | H214: Pins: 6-pin / 8-pin | I214: Mounting: Socket Mount | J214: - | K214: Interface Relay | L214: Stocked | M214: RXG22BD | O214: 865 | P214: =IF(ISNUMBER(O214),O214*(1-N214),O214) | Q214: Harmony RXG | R214: Fast-on pin terminal; Optional lockable test button; 16mm socket width | S214: RGZE sockets | T214: 10 | U214: Pluggable interface relay | V214: 27
A215: 211 | B215: Schneider Electric | C215: Plug-in Relays (Harmony) | D215: 2CO 8 Pin Relay Standard cover lockable test button with LED 120V AC | E215: RXG RXG22F7 | F215: Contacts: 2 CO - 5 A | G215: Control Voltage: 120V AC | H215: Pins: 6-pin / 8-pin | I215: Mounting: Socket Mount | J215: - | K215: Interface Relay | L215: Stocked | M215: RXG22F7 | O215: 1040 | P215: =IF(ISNUMBER(O215),O215*(1-N215),O215) | Q215: Harmony RXG | R215: Fast-on pin terminal; Optional lockable test button; 16mm socket width | S215: RGZE sockets | T215: 10 | U215: Pluggable interface relay | V215: 27
...

Sheet E-Commerce & Catalogue Schema
A1: Schneider Electric Industrial Automation - E-Commerce & Product Master Data
A2: Clean, normalized tabular data ready for ERP, E-Commerce, PIM import, and parametric filtering.
A4: Category | B4: Subcategory | C4: Product Family | D4: Product Code / SKU | E4: Product Name | F4: Description | G4: Voltage Rating (V) | H4: Current Rating (A) | I4: Breaking / Withstand Capacity (kA) | J4: Dimensions (W x D x H mm) | K4: Ingress Protection (IP) | L4: Technical Specifications | M4: Currency | N4: List Price | O4: Discount (%) | P4: Net Price | Q4: Price Status | R4: Availability / Lead Time Details | S4: Installation / Mounting Type | T4: Standards / Compliance | U4: Catalogue Page Reference
A5: Power Supplies (Phaseo) | B5: Panel Mount Switch Mode Power Supply | C5: Phaseo ABL2 | D5: ABL2REM24015K | E5: Phaseo Easy ABL2 35W | F5: ABL2_K Power Supply, DC24V output, 35W | G5: 24V | H5: 1.5A | I5: - | J5: Panel Mount | K5: IP20 | L5: Output stability +/-1%; MTBF >600k hours; Diagnostic LED; Input 100-240V AC | M5: INR | N5: 3061 | P5: =IF(ISNUMBER(N5),N5*(1-O5),N5) | Q5: ok | R5: Normal Stock Item | S5: Panel mount | T5: IEC 60950-1 | U5: Page 5
A6: Power Supplies (Phaseo) | B6: Panel Mount Switch Mode Power Supply | C6: Phaseo ABL2 | D6: ABL2REM24020K | E6: Phaseo Easy ABL2 50W | F6: ABL2_K Power Supply, DC24V output, 50W | G6: 24V | H6: 2A | I6: - | J6: Panel Mount | K6: IP20 | L6: Output stability +/-1%; MTBF >600k hours; Diagnostic LED; Input 100-240V AC | M6: INR | N6: 3393 | P6: =IF(ISNUMBER(N6),N6*(1-O6),N6) | Q6: ok | R6: Normal Stock Item | S6: Panel mount | T6: IEC 60950-1 | U6: Page 5
A7: Power Supplies (Phaseo) | B7: Panel Mount Switch Mode Power Supply | C7: Phaseo ABL2 | D7: ABL2REM24045K | E7: Phaseo Easy ABL2 100W | F7: ABL2_K Power Supply, DC24V output, 100W | G7: 24V | H7: 4.5A | I7: - | J7: Panel Mount | K7: IP20 | L7: Output stability +/-1%; MTBF >600k hours; Diagnostic LED; Input 100-240V AC | M7: INR | N7: 5024 | P7: =IF(ISNUMBER(N7),N7*(1-O7),N7) | Q7: ok | R7: Normal Stock Item | S7: Panel mount | T7: IEC 60950-1 | U7: Page 5
A8: Power Supplies (Phaseo) | B8: Panel Mount Switch Mode Power Supply | C8: Phaseo ABL2 | D8: ABL2REM24065K | E8: Phaseo Easy ABL2 150W | F8: ABL2_K Power Supply, DC24V output, 150W | G8: 24V | H8: 6.5A | I8: - | J8: Panel Mount | K8: IP20 | L8: Output stability +/-1%; MTBF >600k hours; Diagnostic LED; Input 100-240V AC | M8: INR | N8: 6061 | P8: =IF(ISNUMBER(N8),N8*(1-O8),N8) | Q8: ok | R8: Normal Stock Item | S8: Panel mount | T8: IEC 60950-1 | U8: Page 5
A9: Power Supplies (Phaseo) | B9: Panel Mount Switch Mode Power Supply | C9: Phaseo ABL2 | D9: ABL2REM24085K | E9: Phaseo Easy ABL2 200W | F9: ABL2_K Power Supply, DC24V output, 200W | G9: 24V | H9: 8.5A | I9: - | J9: Panel Mount | K9: IP20 | L9: Output stability +/-1%; MTBF >600k hours; Diagnostic LED; Input 100-240V AC | M9: INR | N9: 8038 | P9: =IF(ISNUMBER(N9),N9*(1-O9),N9) | Q9: ok | R9: Normal Stock Item | S9: Panel mount | T9: IEC 60950-1 | U9: Page 5
A10: Power Supplies (Phaseo) | B10: Panel Mount Switch Mode Power Supply | C10: Phaseo ABL2 | D10: ABL2REM24100K | E10: Phaseo Easy ABL2 250W | F10: ABL2_K Power Supply, DC24V output, 250W | G10: 24V | H10: 10A | I10: - | J10: Panel Mount | K10: IP20 | L10: Output stability +/-1%; MTBF >600k hours; Diagnostic LED; Input 100-240V AC | M10: INR | N10: 9194 | P10: =IF(ISNUMBER(N10),N10*(1-O10),N10) | Q10: ok | R10: Normal Stock Item | S10: Panel mount | T10: IEC 60950-1 | U10: Page 5
A11: Power Supplies (Phaseo) | B11: Panel Mount Switch Mode Power Supply | C11: Phaseo ABL2 | D11: ABL2REM24150K | E11: Phaseo Easy ABL2 350W | F11: ABL2_K Power Supply, DC24V output, 350W | G11: 24V | H11: 15A | I11: - | J11: Panel Mount | K11: IP20 | L11: Output stability +/-1%; MTBF >600k hours; Diagnostic LED; Input 100-240V AC | M11: INR | N11: 14992 | P11: =IF(ISNUMBER(N11),N11*(1-O11),N11) | Q11: ok | R11: Normal Stock Item | S11: Panel mount | T11: IEC 60950-1 | U11: Page 5
A12: Power Supplies (Phaseo) | B12: Universal DIN Rail Power Supply | C12: Phaseo ABL8 | D12: ABL8RPS24030 | E12: Phaseo ABL8 72W | F12: Univ. Power Supply 1P 24V 3A, 72W | G12: 24V | H12: 3A | I12: - | J12: DIN Rail 35mm | K12: IP20 | L12: 1 or 2 phase input; Auto/manual reset; 2 diagnosis LEDs; Diagnosis relay output | M12: INR | N12: 21487 | P12: =IF(ISNUMBER(N12),N12*(1-O12),N12) | Q12: ok | R12: Normal Stock Item | S12: DIN Rail 35mm | T12: IEC 61000-6-2 | U12: Page 5
A13: Power Supplies (Phaseo) | B13: Universal DIN Rail Power Supply | C13: Phaseo ABL8 | D13: ABL8RPS24050 | E13: Phaseo ABL8 120W | F13: Univ. Power Supply 1P 24V 5A, 120W | G13: 24V | H13: 5A | I13: - | J13: DIN Rail 35mm | K13: IP20 | L13: 1 or 2 phase input; Auto/manual reset; 2 diagnosis LEDs; Diagnosis relay output | M13: INR | N13: 27778 | P13: =IF(ISNUMBER(N13),N13*(1-O13),N13) | Q13: ok | R13: Normal Stock Item | S13: DIN Rail 35mm | T13: IEC 61000-6-2 | U13: Page 5
A14: Power Supplies (Phaseo) | B14: Universal DIN Rail Power Supply | C14: Phaseo ABL8 | D14: ABL8RPS24100 | E14: Phaseo ABL8 240W | F14: Univ. Power Supply 1P 24V 10A, 240W | G14: 24V | H14: 10A | I14: - | J14: DIN Rail 35mm | K14: IP20 | L14: 1 or 2 phase input; Auto/manual reset; 2 diagnosis LEDs; Diagnosis relay output | M14: INR | N14: 31734 | P14: =IF(ISNUMBER(N14),N14*(1-O14),N14) | Q14: ok | R14: Normal Stock Item | S14: DIN Rail 35mm | T14: IEC 61000-6-2 | U14: Page 5
A15: Power Supplies (Phaseo) | B15: Universal DIN Rail Power Supply | C15: Phaseo ABL8 | D15: ABL8RPM24200 | E15: Phaseo ABL8 480W | F15: Univ. Power Supply 1P 24V 20A, 480W | G15: 24V | H15: 20A | I15: - | J15: DIN Rail 35mm | K15: IP20 | L15: 1 or 2 phase input; Auto/manual reset; 2 diagnosis LEDs; Diagnosis relay output | M15: INR | N15: 47764 | P15: =IF(ISNUMBER(N15),N15*(1-O15),N15) | Q15: ok | R15: Normal Stock Item | S15: DIN Rail 35mm | T15: IEC 61000-6-2 | U15: Page 5
A16: Power Supplies (Phaseo) | B16: Optimised DIN Rail Power Supply | C16: Phaseo ABLS | D16: ABLS1A12062 | E16: Phaseo ABLS 75W | F16: POWER SUPPLY 12V 6.2A 1PH OPTIMIZED | G16: 12V | H16: 6.2A | I16: - | J16: Compact DIN Rail | K16: IP20 | L16: Conformal coating; 6 output terminals; High output stability; Operating up to +70 deg C | M16: INR | N16: 10652 | P16: =IF(ISNUMBER(N16),N16*(1-O16),N16) | Q16: ok | R16: Normal Stock Item | S16: DIN Rail 35mm | T16: IEC 62368-1 | U16: Page 6
... A75: Smart Relays (Harmony Zelio) | B75: Zelio Extension Modules & Accessories | C75: Harmony Zelio | D75: SR2USB01 | E75: Zelio Acc SR2USB01 | F75: USB PC connecting cable - 3 m | G75: Cable | H75: - | I75: - | J75: Modular expansion | K75: IP20 | L75: USB PC connecting cable - 3 m | M75: INR | N75: 20194 | P75: =IF(ISNUMBER(N75),N75*(1-O75),N75) | Q75: ok | R75: Normal Stock Item | S75: Side mounting on SR3 | T75: IEC 61131-2 | U75: Page 8
A76: Variable Speed Drives (Altivar) | B76: General Purpose AC Drives | C76: Altivar ATV12 / ATV310 | D76: ATV12H018M2 | E76: Altivar ATV12H018M2 | F76: Altivar 12 Drive 0.18kW 0.25HP 1-Phase 200-240V | G76: 1-Ph 200-240V | H76: 1.4A | I76: - | J76: Compact Enclosure | K76: IP20 | L76: Integrated Modbus; 55 deg C without derating; Optimized panel space; Built-in brake chopper | M76: INR | N76: On Request | P76: =IF(ISNUMBER(N76),N76*(1-O76),N76) | Q76: on request | R76: Normal Stock Item | S76: Panel Mount / DIN Rail | T76: IEC 61800-5-1 | U76: Page 11
A77: Variable Speed Drives (Altivar) | B77: General Purpose AC Drives | C77: Altivar ATV12 / ATV310 | D77: ATV12H037M2 | E77: Altivar ATV12H037M2 | F77: Altivar 12 Drive 0.37kW 0.55HP 1-Phase 200-240V | G77: 1-Ph 200-240V | H77: 2.4A | I77: - | J77: Compact Enclosure | K77: IP20 | L77: Integrated Modbus; 55 deg C without derating; Optimized panel space; Built-in brake chopper | M77: INR | N77: On Request | P77: =IF(ISNUMBER(N77),N77*(1-O77),N77) | Q77: on request | R77: Normal Stock Item | S77: Panel Mount / DIN Rail | T77: IEC 61800-5-1 | U77: Page 11
A78: Variable Speed Drives (Altivar) | B78: General Purpose AC Drives | C78: Altivar ATV12 / ATV310 | D78: ATV12H055M2 | E78: Altivar ATV12H055M2 | F78: Altivar 12 Drive 0.55kW 0.75HP 1-Phase 200-240V | G78: 1-Ph 200-240V | H78: 3.5A | I78: - | J78: Compact Enclosure | K78: IP20 | L78: Integrated Modbus; 55 deg C without derating; Optimized panel space; Built-in brake chopper | M78: INR | N78: On Request | P78: =IF(ISNUMBER(N78),N78*(1-O78),N78) | Q78: on request | R78: Normal Stock Item | S78: Panel Mount / DIN Rail | T78: IEC 61800-5-1 | U78: Page 11
A79: Variable Speed Drives (Altivar) | B79: General Purpose AC Drives | C79: Altivar ATV12 / ATV310 | D79: ATV12H075M2 | E79: Altivar ATV12H075M2 | F79: Altivar 12 Drive 0.75kW 1HP 1-Phase 200-240V | G79: 1-Ph 200-240V | H79: 4.2A | I79: - | J79: Compact Enclosure | K79: IP20 | L79: Integrated Modbus; 55 deg C without derating; Optimized panel space; Built-in brake chopper | M79: INR | N79: On Request | P79: =IF(ISNUMBER(N79),N79*(1-O79),N79) | Q79: on request | R79: Normal Stock Item | S79: Panel Mount / DIN Rail | T79: IEC 61800-5-1 | U79: Page 11
A80: Variable Speed Drives (Altivar) | B80: General Purpose AC Drives | C80: Altivar ATV12 / ATV310 | D80: ATV12HU15M2 | E80: Altivar ATV12HU15M2 | F80: Altivar 12 Drive 1.5kW 2HP 1-Phase 200-240V | G80: 1-Ph 200-240V | H80: 7.5A | I80: - | J80: Compact Enclosure | K80: IP20 | L80: Integrated Modbus; 55 deg C without derating; Optimized panel space; Built-in brake chopper | M80: INR | N80: On Request | P80: =IF(ISNUMBER(N80),N80*(1-O80),N80) | Q80: on request | R80: Normal Stock Item | S80: Panel Mount / DIN Rail | T80: IEC 61800-5-1 | U80: Page 11
A81: Variable Speed Drives (Altivar) | B81: General Purpose AC Drives | C81: Altivar ATV12 / ATV310 | D81: ATV12HU22M2 | E81: Altivar ATV12HU22M2 | F81: Altivar 12 Drive 2.2kW 3HP 1-Phase 200-240V | G81: 1-Ph 200-240V | H81: 10A | I81: - | J81: Compact Enclosure | K81: IP20 | L81: Integrated Modbus; 55 deg C without derating; Optimized panel space; Built-in brake chopper | M81: INR | N81: On Request | P81: =IF(ISNUMBER(N81),N81*(1-O81),N81) | Q81: on request | R81: Normal Stock Item | S81: Panel Mount / DIN Rail | T81: IEC 61800-5-1 | U81: Page 11
A82: Variable Speed Drives (Altivar) | B82: General Purpose AC Drives | C82: Altivar ATV12 / ATV310 | D82: ATV12H037M3 | E82: Altivar ATV12H037M3 | F82: Altivar 12 Drive 0.37kW 0.55HP 3-Phase 200-240V | G82: 3-Ph 200-240V | H82: 2.4A | I82: - | J82: Compact Enclosure | K82: IP20 | L82: Integrated Modbus; 55 deg C without derating; Optimized panel space; Built-in brake chopper | M82: INR | N82: On Request | P82: =IF(ISNUMBER(N82),N82*(1-O82),N82) | Q82: on request | R82: Normal Stock Item | S82: Panel Mount / DIN Rail | T82: IEC 61800-5-1 | U82: Page 11
A83: Variable Speed Drives (Altivar) | B83: General Purpose AC Drives | C83: Altivar ATV12 / ATV310 | D83: ATV12H075M3 | E83: Altivar ATV12H075M3 | F83: Altivar 12 Drive 0.75kW 1HP 3-Phase 200-240V | G83: 3-Ph 200-240V | H83: 4.2A | I83: - | J83: Compact Enclosure | K83: IP20 | L83: Integrated Modbus; 55 deg C without derating; Optimized panel space; Built-in brake chopper | M83: INR | N83: On Request | P83: =IF(ISNUMBER(N83),N83*(1-O83),N83) | Q83: on request | R83: Normal Stock Item | S83: Panel Mount / DIN Rail | T83: IEC 61800-5-1 | U83: Page 11
A84: Variable Speed Drives (Altivar) | B84: General Purpose AC Drives | C84: Altivar ATV12 / ATV310 | D84: ATV12HU15M3 | E84: Altivar ATV12HU15M3 | F84: Altivar 12 Drive 1.5kW 2HP 3-Phase 200-240V | G84: 3-Ph 200-240V | H84: 7.5A | I84: - | J84: Compact Enclosure | K84: IP20 | L84: Integrated Modbus; 55 deg C without derating; Optimized panel space; Built-in brake chopper | M84: INR | N84: On Request | P84: =IF(ISNUMBER(N84),N84*(1-O84),N84) | Q84: on request | R84: Normal Stock Item | S84: Panel Mount / DIN Rail | T84: IEC 61800-5-1 | U84: Page 11
A85: Variable Speed Drives (Altivar) | B85: General Purpose AC Drives | C85: Altivar ATV12 / ATV310 | D85: ATV12HU22M3 | E85: Altivar ATV12HU22M3 | F85: Altivar 12 Drive 2.2kW 3HP 3-Phase 200-240V | G85: 3-Ph 200-240V | H85: 10A | I85: - | J85: Compact Enclosure | K85: IP20 | L85: Integrated Modbus; 55 deg C without derating; Optimized panel space; Built-in brake chopper | M85: INR | N85: On Request | P85: =IF(ISNUMBER(N85),N85*(1-O85),N85) | Q85: on request | R85: Normal Stock Item | S85: Panel Mount / DIN Rail | T85: IEC 61800-5-1 | U85: Page 11
A86: Variable Speed Drives (Altivar) | B86: General Purpose AC Drives | C86: Altivar ATV12 / ATV310 | D86: ATV12HU30M3 | E86: Altivar ATV12HU30M3 | F86: Altivar 12 Drive 3kW 3-Phase 200-240V | G86: 3-Ph 200-240V | H86: 12.2A | I86: - | J86: Compact Enclosure | K86: IP20 | L86: Integrated Modbus; 55 deg C without derating; Optimized panel space; Built-in brake chopper | M86: INR | N86: On Request | P86: =IF(ISNUMBER(N86),N86*(1-O86),N86) | Q86: on request | R86: Normal Stock Item | S86: Panel Mount / DIN Rail | T86: IEC 61800-5-1 | U86: Page 11
A87: Variable Speed Drives (Altivar) | B87: General Purpose AC Drives | C87: Altivar ATV12 / ATV310 | D87: ATV12HU40M3 | E87: Altivar ATV12HU40M3 | F87: Altivar 12 Drive 4kW 5HP 3-Phase 200-240V | G87: 3-Ph 200-240V | H87: 16.7A | I87: - | J87: Compact Enclosure | K87: IP20 | L87: Integrated Modbus; 55 deg C without derating; Optimized panel space; Built-in brake chopper | M87: INR | N87: On Request | P87: =IF(ISNUMBER(N87),N87*(1-O87),N87) | Q87: on request | R87: Normal Stock Item | S87: Panel Mount / DIN Rail | T87: IEC 61800-5-1 | U87: Page 11
... A204: Soft Starters (Altistart/Altivar) | B204: ATS490 Advanced Soft Starters | C204: Altivar ATS490 | D204: ATS490M12Y | E204: ATS490 ATS490M12Y | F204: ATS490 Soft Starter 1200A 630-900kW | G204: 208-690V | H204: 1200A | I204: - | J204: Panel mount enclosure | K204: IP00 / IP20 | L204: Torque control original; Integrated bypass; Cybersecure IEC 62443; Modbus TCP / Ethernet IP | M204: INR | N204: On Request | P204: =IF(ISNUMBER(N204),N204*(1-O204),N204) | Q204: on request | R204: Normal Stock Item | S204: Panel Mount | T204: IEC 60947-4-2 | U204: Page 25
A205: Plug-in Relays (Harmony) | B205: Interface Relays (RXG) | C205: Harmony RXG | D205: RXG11BD | E205: RXG RXG11BD | F205: 1CO 6 Pin Relay Standard cover lockable test button w/o LED 24V DC | G205: 24V DC | H205: 1 CO - 10 A | I205: - | J205: 16mm socket width | K205: IP40 | L205: Fast-on pin terminal; Optional lockable test button; 16mm socket width | M205: INR | N205: 690 | P205: =IF(ISNUMBER(N205),N205*(1-O205),N205) | Q205: ok | R205: Normal Stock Item | S205: Socket on DIN rail | T205: IEC 61810-1 | U205: Page 27
A206: Plug-in Relays (Harmony) | B206: Interface Relays (RXG) | C206: Harmony RXG | D206: RXG11F7 | E206: RXG RXG11F7 | F206: 1CO 6 Pin Relay Standard cover lockable test button w/o LED 120V AC | G206: 120V AC | H206: 1 CO - 10 A | I206: - | J206: 16mm socket width | K206: IP40 | L206: Fast-on pin terminal; Optional lockable test button; 16mm socket width | M206: INR | N206: 911 | P206: =IF(ISNUMBER(N206),N206*(1-O206),N206) | Q206: ok | R206: Normal Stock Item | S206: Socket on DIN rail | T206: IEC 61810-1 | U206: Page 27
A207: Plug-in Relays (Harmony) | B207: Interface Relays (RXG) | C207: Harmony RXG | D207: RXG11P7 | E207: RXG RXG11P7 | F207: 1CO 6 Pin Relay Standard cover lockable test button w/o LED 230V AC | G207: 230V AC | H207: 1 CO - 10 A | I207: - | J207: 16mm socket width | K207: IP40 | L207: Fast-on pin terminal; Optional lockable test button; 16mm socket width | M207: INR | N207: 859 | P207: =IF(ISNUMBER(N207),N207*(1-O207),N207) | Q207: ok | R207: Normal Stock Item | S207: Socket on DIN rail | T207: IEC 61810-1 | U207: Page 27
A208: Plug-in Relays (Harmony) | B208: Interface Relays (RXG) | C208: Harmony RXG | D208: RXG12BD | E208: RXG RXG12BD | F208: 1CO 6 Pin Relay Standard cover lockable test button with LED 24V DC | G208: 24V DC | H208: 1 CO - 10 A | I208: - | J208: 16mm socket width | K208: IP40 | L208: Fast-on pin terminal; Optional lockable test button; 16mm socket width | M208: INR | N208: 779 | P208: =IF(ISNUMBER(N208),N208*(1-O208),N208) | Q208: ok | R208: Normal Stock Item | S208: Socket on DIN rail | T208: IEC 61810-1 | U208: Page 27
A209: Plug-in Relays (Harmony) | B209: Interface Relays (RXG) | C209: Harmony RXG | D209: RXG12F7 | E209: RXG RXG12F7 | F209: 1CO 6 Pin Relay Standard cover lockable test button with LED 120V AC | G209: 120V AC | H209: 1 CO - 10 A | I209: - | J209: 16mm socket width | K209: IP40 | L209: Fast-on pin terminal; Optional lockable test button; 16mm socket width | M209: INR | N209: 934 | P209: =IF(ISNUMBER(N209),N209*(1-O209),N209) | Q209: ok | R209: Normal Stock Item | S209: Socket on DIN rail | T209: IEC 61810-1 | U209: Page 27
A210: Plug-in Relays (Harmony) | B210: Interface Relays (RXG) | C210: Harmony RXG | D210: RXG12P7 | E210: RXG RXG12P7 | F210: 1CO 6 Pin Relay Standard cover lockable test button with LED 230V AC | G210: 230V AC | H210: 1 CO - 10 A | I210: - | J210: 16mm socket width | K210: IP40 | L210: Fast-on pin terminal; Optional lockable test button; 16mm socket width | M210: INR | N210: 934 | P210: =IF(ISNUMBER(N210),N210*(1-O210),N210) | Q210: ok | R210: Normal Stock Item | S210: Socket on DIN rail | T210: IEC 61810-1 | U210: Page 27
A211: Plug-in Relays (Harmony) | B211: Interface Relays (RXG) | C211: Harmony RXG | D211: RXG21BD | E211: RXG RXG21BD | F211: 2CO 8 Pin Relay Standard cover lockable test button w/o LED 24V DC | G211: 24V DC | H211: 2 CO - 5 A | I211: - | J211: 16mm socket width | K211: IP40 | L211: Fast-on pin terminal; Optional lockable test button; 16mm socket width | M211: INR | N211: 778 | P211: =IF(ISNUMBER(N211),N211*(1-O211),N211) | Q211: ok | R211: Normal Stock Item | S211: Socket on DIN rail | T211: IEC 61810-1 | U211: Page 27
A212: Plug-in Relays (Harmony) | B212: Interface Relays (RXG) | C212: Harmony RXG | D212: RXG21F7 | E212: RXG RXG21F7 | F212: 2CO 8 Pin Relay Standard cover lockable test button w/o LED 120V AC | G212: 120V AC | H212: 2 CO - 5 A | I212: - | J212: 16mm socket width | K212: IP40 | L212: Fast-on pin terminal; Optional lockable test button; 16mm socket width | M212: INR | N212: 944 | P212: =IF(ISNUMBER(N212),N212*(1-O212),N212) | Q212: ok | R212: Normal Stock Item | S212: Socket on DIN rail | T212: IEC 61810-1 | U212: Page 27
A213: Plug-in Relays (Harmony) | B213: Interface Relays (RXG) | C213: Harmony RXG | D213: RXG21P7 | E213: RXG RXG21P7 | F213: 2CO 8 Pin Relay Standard cover lockable test button w/o LED 230V AC | G213: 230V AC | H213: 2 CO - 5 A | I213: - | J213: 16mm socket width | K213: IP40 | L213: Fast-on pin terminal; Optional lockable test button; 16mm socket width | M213: INR | N213: 926 | P213: =IF(ISNUMBER(N213),N213*(1-O213),N213) | Q213: ok | R213: Normal Stock Item | S213: Socket on DIN rail | T213: IEC 61810-1 | U213: Page 27
A214: Plug-in Relays (Harmony) | B214: Interface Relays (RXG) | C214: Harmony RXG | D214: RXG22BD | E214: RXG RXG22BD | F214: 2CO 8 Pin Relay Standard cover lockable test button with LED 24V DC | G214: 24V DC | H214: 2 CO - 5 A | I214: - | J214: 16mm socket width | K214: IP40 | L214: Fast-on pin terminal; Optional lockable test button; 16mm socket width | M214: INR | N214: 865 | P214: =IF(ISNUMBER(N214),N214*(1-O214),N214) | Q214: ok | R214: Normal Stock Item | S214: Socket on DIN rail | T214: IEC 61810-1 | U214: Page 27
A215: Plug-in Relays (Harmony) | B215: Interface Relays (RXG) | C215: Harmony RXG | D215: RXG22F7 | E215: RXG RXG22F7 | F215: 2CO 8 Pin Relay Standard cover lockable test button with LED 120V AC | G215: 120V AC | H215: 2 CO - 5 A | I215: - | J215: 16mm socket width | K215: IP40 | L215: Fast-on pin terminal; Optional lockable test button; 16mm socket width | M215: INR | N215: 1040 | P215: =IF(ISNUMBER(N215),N215*(1-O215),N215) | Q215: ok | R215: Normal Stock Item | S215: Socket on DIN rail | T215: IEC 61810-1 | U215: Page 27
...

Sheet Notes
A1: How to use
A2: Discount | B2: Column N (Schneider Automation Price List) is formatted as percentage. Type discount (e.g. 35%). Net Price (Column P) calculates automatically via =IF(ISNUMBER(Price), Price*(1-Discount), Price).
A3: Price | B3: List price (M.R.P.) in Indian Rupees (INR) as printed in the Schneider Electric Industrial Automation Products price list effective April 01st, 2026. 'On Request' denotes engineered/OEM configurations.
A4: Ratings 1-5 | B4: Price-driving ratings structured as 'Header: value' (e.g. Voltage: 24V DC, Current: 25A, Poles: 3P, Power: 11kW, Sensitivity: 30mA).
A5: Key word | B5: Type reference / model designation distinguishing each SKU (e.g. ABL2REM, ATV310, ATS480, RXM, LC1D, LRD, GV2ME, xC60).
A6: Accessories | B6: Indicates whether the reference is a complete unit, auxiliary contact block, mounting kit, coil suppressor, communication module, or spare part.
A7: Stocked / Availability | B7: Green tick symbol in the price list denotes 'Normal Stock Item'. Others are available on lead time.
A8: Coil Codes | B8: For contactors with asterisks (e.g., LC1D09*), standard AC coils are B7 (24V), F7 (110V), M7 (220V), N7 (415V); DC coils are BD (24V), FD (110V), MD (220V).
A9: Source | B9: Schneider Electric Industrial Automation Products Price List (Ref: se.com/in, W.E.F. April 01st, 2026).
A11: Standard Compliance | B11: IEC 60947-4-1 (Contactors/Starters), IEC 60947-2 (Circuit Breakers), IEC 60898-1 (MCBs), IEC 61008/61009 (RCDs), IEC 61643-11 (Surge Protection), IEC 60255 (Relays).

Sheet Summary
A1: Category | B1: No. of items
A2: Power Supplies (Phaseo) | B2: =COUNTIF('Schneider Automation Price List'!$C$5:$C$702,A2)
A3: Smart Relays (Harmony Zelio) | B3: =COUNTIF('Schneider Automation Price List'!$C$5:$C$702,A3)
A4: Variable Speed Drives (Altivar) | B4: =COUNTIF('Schneider Automation Price List'!$C$5:$C$702,A4)
A5: Soft Starters (Altistart/Altivar) | B5: =COUNTIF('Schneider Automation Price List'!$C$5:$C$702,A5)
A6: Plug-in Relays (Harmony) | B6: =COUNTIF('Schneider Automation Price List'!$C$5:$C$702,A6)
A7: Timing & Control Relays (Harmony) | B7: =COUNTIF('Schneider Automation Price List'!$C$5:$C$702,A7)
A8: Pushbuttons & Signaling (Harmony) | B8: =COUNTIF('Schneider Automation Price List'!$C$5:$C$702,A8)
A9: HMI Panels & Industrial PCs | B9: =COUNTIF('Schneider Automation Price List'!$C$5:$C$702,A9)
A10: HMI Software & Remote Access | B10: =COUNTIF('Schneider Automation Price List'!$C$5:$C$702,A10)
A11: Power Contactors (TeSys K/Deca/Giga) | B11: =COUNTIF('Schneider Automation Price List'!$C$5:$C$702,A11)
A12: Control Relays (TeSys) | B12: =COUNTIF('Schneider Automation Price List'!$C$5:$C$702,A12)
A13: Thermal Overload Relays (TeSys Protect) | B13: =COUNTIF('Schneider Automation Price List'!$C$5:$C$702,A13)
... A22: Control & Command (Acti 9) | B22: =COUNTIF('Schneider Automation Price List'!$C$5:$C$702,A22)
A23: Total Items | B23: =SUM(B2:B22)
